Workbook
Name \0: #REF!
Name \0: #REF!
Name \0: #REF!
Name \0: #REF!
Name \0: #REF!
Name \0: #REF!
Name \0: #REF!
Name \0: #REF!
Name \0: #REF!
Name \0: #REF!
Name \0: #REF!
Name \0: #REF!
Name \0: #REF!
Name \0: #REF!
Name \0: #REF!
Name \0: #REF!
Name \0: #REF!
Name \0: #REF!
Name \0: #REF!
Name \0: #REF!
Name \0: #REF!
Name \0: #REF!
Name \0: #REF!
Name \0: #REF!
Name \0: #REF!
Name \0: #REF!
Name \0: #REF!
Name \0: #REF!
Name \0: #REF!
Name \0: #REF!
Name \0: #REF!
Name \0: #REF!
Name \0: #REF!
Name \0: #REF!
Name \0: #REF!
Name \0: #REF!
Name \0: #REF!
Name \0: #REF!
Name \0: #REF!
Name \0: #REF!
Name \0: #REF!
Name \0: #REF!
Name \0: #REF!
Name \0: #REF!
Name \0: #REF!
Name \0: #REF!
Name \0: #REF!
Name \0: #REF!
Name \0: #REF!
Name \0: #REF!
Name \0: #REF!
Name \0: #REF!
Name \0: #REF!
Name \0: #REF!
Name \00: #REF!
Name \00: #REF!
Name \00: #REF!
Name \00: #REF!
Name \a: #REF!
Name \a: #REF!

Sheet PLAN AUTORIZADO
C2: PLAN DE INTERVENCIÓN ESPECIFICO
D3: CONTRATO No. | F3: OBJETO: SERVICIO PARA LA OPERACIÓN DE LA MAQUINARIA AMARILLA ADSCRITA A LA DIRECCIÓN DEPARTAMENTAL PARA LA GESTIÓN DEL RIESGO DE DESASTRES PARA LA REDUCCIÓN DEL RIESGO EN LOS VEINTINUEVE (29) MUNICIPIOS DEL DEPARTAMENTO DEL META.
C4: PRESUPUESTO OPERACIÓN MAQUINARIA: | F4: 671921001 | G4: FECHA DE INICIO: | J4: FECHA DIA QUE SE ACTUALIZO:
C5: VALOR TOTAL CONTRATO INCLUYE IVA: | F5: =+F4*1.19 -> 7.9958599e+08 | G5: FECHA TERMINACIÓN: | J5: SUPERVISOR: | N5: APOYO A LA SUPERVISION:
A7: CONTRATO INICIAL
A8: N° PUNTO | B8: MUNICIPIO | C8: ZONA ESPECIFICA | D8: ACCIONES A REALIZAR | E8: RIESGO DE UN POSIBLE DESASTRE NATURAL O CALAMIDAD PUBLICA | F8: HORAS PROYECTADAS | J8: HORAS EJECUTADAS | L8: HORAS PROGRAMADAS | N8: OBSERVACIONES | O8: COORDINADOR DIGERD
F9: TIPO DE MAQUINA | G9: CANT. HORAS | H9: VALOR UNITARIO | I9: VALOR ($) | J9: CANT. HORAS | K9: VALOR ($) | L9: CANT. HORAS | M9: VALOR ($)
A10: 1 | B10: EL CALVARIO | C10: VEREDA EL CARMEN 73°43'48.51"O 4°20'41.81"N | D10: REHABILITACION PUNTOS CRÍTICOS VIA TERCIARIA. | E10: DERRUMBES, AFECTACIÓN DE LA VIA | F10: FUNCIONAMIENTO Y OPERACIÓN DE BULLDOZER SOBRE ORUGA CATERPILLAR D6K XL | G10: 75 | H10: 443300 | I10: =+G10*H10 -> 33247500 | J10: 0 | K10: =+J10*H10 -> 0 | L10: =+G10-J10 -> 75 | M10: =+L10*H10 -> 33247500 | N10: DE LAS 100 HORAS DE BULLDOZER ASIGNADAS AL PUNTO; 75 HORAS SE USARAN PARA LA INTERVENCIÓN, LAS CUALES INCLUYEN EL DESPLAZAMIENTO DE LA MAQUINA DESDE EL PUNTO ACTUAL DE PARQUEO HASTA EL PUNTO DE TRABAJO. LAS 25 HORAS RESTANTES SE DESTINAN PARA QUE EL BULLDOZER SE TRASLADE POR SUS PROPIOS MEDIOS HASTA EL SITIO MONTEREDONDO DONDE SERÁ RECOGIDO POR EL TRACTO CAMIÓN CAMABAJA. UNA VEZ FINALIZA LA INTERVENCIÓN LA MAQUINA UTILIZARA 25 HORAS PARA DESPLAZARCE DESDE EL PUNTO DE TRABAJO HASTA EL PUNTO DE EMBARCACIÓN A LA CAMA BAJA. | Q10: =+G10+G16+G21+G26+G31+G36+G41+G46+G11 -> 100
F11: FUNCIONAMIENTO Y OPERACIÓN DE BULLDOZER SOBRE ORUGA CATERPILLAR D6K XL | G11: 25 | H11: 443300 | I11: =+G11*H11 -> 11082500 | J11: 0 | K11: =+J11*H11 -> 0 | L11: =+G11-J11 -> 25 | M11: =+L11*H11 -> 11082500
F12: FUNCIONAMIENTO Y OPERACIÓN DE EXCAVADORA SOBRE ORUGA LINK-BELT 210 X2 | G12: 0 | H12: 460400 | I12: =+G12*H12 -> 0 | J12: 0 | K12: =+J12*H12 -> 0 | L12: 0 | M12: =+L12*H12 -> 0 | Q12: =+G12+G17+G22+G27+G32+G42+G47+G37 -> 550
F13: FUNCIONAMIENTO Y OPERACIÓN DE VOLQUETA SENCILLA FTR CHEVROLET | G13: 0 | H13: 278400 | I13: =+G13*H13 -> 0 | J13: 0 | K13: =+J13*H13 -> 0 | L13: 0 | M13: =+L13*H13 -> 0 | Q13: =+G13+G18+G23+G28+G33+G38+G43+G48 -> 0
F14: FUNCIONAMIENTO Y OPERACIÓN DE RETROEXCAVADORA CATERPILLAR 416 E | G14: 0 | H14: 325000 | I14: =+G14*H14 -> 0 | J14: 0 | K14: =+J14*H14 -> 0 | L14: 0 | M14: =+L14*H14 -> 0 | Q14: =+G14+G19+G24+G29+G34+G39+G44+G49 -> 0
H15: SUBTOTAL | I15: =SUM(I10:I14) -> 44330000 | K15: =SUM(K10:K14) -> 0 | M15: =SUM(M10:M14) -> 44330000
A16: 2 | B16: GUAMAL | C16: PIO XII 73°48'9.28"O 3°54'14.01"N | D16: DESCOLMATACIÓN, ENCAUZAMIENTO O CONFORMACIÓN DE JARILLONES | E16: DESBORDAMIENTO E INUNDACIÓN | F16: FUNCIONAMIENTO Y OPERACIÓN DE BULLDOZER SOBRE ORUGA CATERPILLAR D6K XL | G16: 0 | H16: 443300 | I16: =+G16*H16 -> 0 | J16: 0 | K16: =+J16*H16 -> 0 | L16: 0 | M16: =+L16*H16 -> 0 | N16: LAS 200 HORAS ASIGNADAS SON INSUFICIENTES PARA ATENDER ADECUADAMENTE LA AFECTACIÓN POR DESBORADAMIENTO E INUNDACIÓN DEL RIO GUAMAL EN EL SECTOR PIO XII, YA QUE SON MÁS DE 2 BRAZOS DEL RÍO QUE ATACAN LA MARGEN IZQUIERDA DEL RÍO GUAMAL LO QUE REQUIERE CONTAR CON HORAS SUFICIENTE PARA EJECUTAR LOS TRABAJOS AGUAS ARRIBA DE MANERA EFICIENTE.
F17: FUNCIONAMIENTO Y OPERACIÓN DE EXCAVADORA SOBRE ORUGA LINK-BELT 210 X2 | G17: 200 | H17: 460400 | I17: =+G17*H17 -> 92080000 | J17: 0 | K17: =+J17*H17 -> 0 | L17: =+G17-J17 -> 200 | M17: =+L17*H17 -> 92080000
F18: FUNCIONAMIENTO Y OPERACIÓN DE VOLQUETA SENCILLA FTR CHEVROLET | G18: 0 | H18: 278400 | I18: =+G18*H18 -> 0 | J18: 0 | K18: =+J18*H18 -> 0 | L18: 0 | M18: =+L18*H18 -> 0
F19: FUNCIONAMIENTO Y OPERACIÓN DE RETROEXCAVADORA CATERPILLAR 416 E | G19: 0 | H19: 325000 | I19: =+G19*H19 -> 0 | J19: 0 | K19: =+J19*H19 -> 0 | L19: 0 | M19: =+L19*H19 -> 0
H20: SUBTOTAL | I20: =SUM(I16:I19) -> 92080000 | K20: =SUM(K16:K19) -> 0 | M20: =SUM(M16:M19) -> 92080000
A21: 3 | B21: GRANADA | C21: PUENTE CAÑO URICHARE 73°43'35.18"O 3°25'3.11"N | D21: DESCOLMATACIÓN, ENCAUZAMIENTO O CONFORMACIÓN DE JARILLONES | E21: DESBORDAMIENTO E INUNDACIÓN | F21: FUNCIONAMIENTO Y OPERACIÓN DE BULLDOZER SOBRE ORUGA CATERPILLAR D6K XL | G21: 0 | H21: 443300 | I21: =+G21*H21 -> 0 | J21: 0 | K21: =+J21*H21 -> 0 | L21: 0 | M21: =+L21*H21 -> 0 | N21: EL MUNICIPIO DE GRANADA REQUIERE HACER CONCERTACIÓN CON EL INVIAS PARA DETERMINAR EL TIPO ESPECÍFICO DE TRABAJO EN LA ZONA DE INFLUENCIA DEL PUENTE
F22: FUNCIONAMIENTO Y OPERACIÓN DE EXCAVADORA SOBRE ORUGA LINK-BELT 210 X2 | G22: 100 | H22: 460400 | I22: =+G22*H22 -> 46040000 | J22: 0 | K22: =+J22*H22 -> 0 | L22: =+G22-J22 -> 100 | M22: =+L22*H22 -> 46040000
F23: FUNCIONAMIENTO Y OPERACIÓN DE VOLQUETA SENCILLA FTR CHEVROLET | G23: 0 | H23: 278400 | I23: =+G23*H23 -> 0 | J23: 0 | K23: =+J23*H23 -> 0 | L23: 0 | M23: =+L23*H23 -> 0
F24: FUNCIONAMIENTO Y OPERACIÓN DE RETROEXCAVADORA CATERPILLAR 416 E | G24: 0 | H24: 325000 | I24: =+G24*H24 -> 0 | J24: 0 | K24: =+J24*H24 -> 0 | L24: 0 | M24: =+L24*H24 -> 0
H25: SUBTOTAL | I25: =SUM(I21:I24) -> 46040000 | K25: =SUM(K21:K24) -> 0 | M25: =SUM(M21:M24) -> 46040000
A26: 4 | B26: VILLAVICENCIO | C26: PALMARITO ARRAYANES 73°19'6.96"O 3°57'54.72"N | D26: DESCOLMATACIÓN, ENCAUZAMIENTO O CONFORMACIÓN DE JARILLONES | E26: DESBORDAMIENTO E INUNDACIÓN | F26: FUNCIONAMIENTO Y OPERACIÓN DE BULLDOZER SOBRE ORUGA CATERPILLAR D6K XL | G26: 0 | H26: 443300 | I26: =+G26*H26 -> 0 | J26: 0 | K26: =+J26*H26 -> 0 | L26: 0 | M26: =+L26*H26 -> 0 | N26: LA MAGNITUD DE AFECTACIÓN DE ESTE PUNTO ES MUY GRANDE POR LO QUE SE REQUIERE INICIAR INTERVENCIÓN EN ÉPOCAS EN LA QUE EL RÍO HAYA BAJADO SU NIVEL
F27: FUNCIONAMIENTO Y OPERACIÓN DE EXCAVADORA SOBRE ORUGA LINK-BELT 210 X2 | G27: 250 | H27: 460400 | I27: =+G27*H27 -> 115100000 | J27: 0 | K27: =+J27*H27 -> 0 | L27: =+G27-J27 -> 250 | M27: =+L27*H27 -> 115100000
F28: FUNCIONAMIENTO Y OPERACIÓN DE VOLQUETA SENCILLA FTR CHEVROLET | G28: 0 | H28: 278400 | I28: =+G28*H28 -> 0 | J28: 0 | K28: =+J28*H28 -> 0 | L28: 0 | M28: =+L28*H28 -> 0
F29: FUNCIONAMIENTO Y OPERACIÓN DE RETROEXCAVADORA CATERPILLAR 416 E | G29: 0 | H29: 325000 | I29: =+G29*H29 -> 0 | J29: 0 | K29: =+J29*H29 -> 0 | L29: 0 | M29: =+L29*H29 -> 0
H30: SUBTOTAL | I30: =SUM(I26:I29) -> 115100000 | K30: =SUM(K26:K29) -> 0 | M30: =SUM(M26:M29) -> 115100000
A31: 5 | F31: FUNCIONAMIENTO Y OPERACIÓN DE BULLDOZER SOBRE ORUGA CATERPILLAR D6K XL | G31: 0 | H31: 443300 | I31: =+G31*H31 -> 0 | J31: 0 | K31: =+J31*H31 -> 0 | L31: 0 | M31: =+L31*H31 -> 0 | N31: INFORMACION ENTREGADA POR RIESGOS MUNICIPAL NO SE HA HECHO VISITA
F32: FUNCIONAMIENTO Y OPERACIÓN DE EXCAVADORA SOBRE ORUGA LINK-BELT 210 X2 | G32: 0 | H32: 460400 | I32: =+G32*H32 -> 0 | J32: 0 | K32: =+J32*H32 -> 0 | L32: =+G32-J32 -> 0 | M32: =+L32*H32 -> 0
F33: FUNCIONAMIENTO Y OPERACIÓN DE VOLQUETA SENCILLA FTR CHEVROLET | G33: 0 | H33: 278400 | I33: =+G33*H33 -> 0 | J33: 0 | K33: =+J33*H33 -> 0 | L33: =+G33-J33 -> 0 | M33: =+L33*H33 -> 0
F34: FUNCIONAMIENTO Y OPERACIÓN DE RETROEXCAVADORA CATERPILLAR 416 E | G34: 0 | H34: 325000 | I34: =+G34*H34 -> 0 | J34: 0 | K34: =+J34*H34 -> 0 | L34: 0 | M34: =+L34*H34 -> 0
H35: SUBTOTAL | I35: =SUM(I31:I34) -> 0 | K35: =SUM(K31:K34) -> 0 | M35: =SUM(M31:M34) -> 0
A36: 6 | F36: FUNCIONAMIENTO Y OPERACIÓN DE BULLDOZER SOBRE ORUGA CATERPILLAR D6K XL | G36: 0 | H36: 443300 | I36: =+G36*H36 -> 0 | J36: 0 | K36: =+J36*H36 -> 0 | L36: 0 | M36: =+L36*H36 -> 0 | N36: INFORMACION ENTREGADA POR RIESGOS MUNICIPAL NO SE HA HECHO VISITA
F37: FUNCIONAMIENTO Y OPERACIÓN DE EXCAVADORA SOBRE ORUGA LINK-BELT 210 X2 | G37: 0 | H37: 460400 | I37: =+G37*H37 -> 0 | J37: 0 | K37: =+J37*H37 -> 0 | L37: =+G37-J37 -> 0 | M37: =+L37*H37 -> 0
F38: FUNCIONAMIENTO Y OPERACIÓN DE VOLQUETA SENCILLA FTR CHEVROLET | G38: 0 | H38: 278400 | I38: =+G38*H38 -> 0 | J38: 0 | K38: =+J38*H38 -> 0 | L38: =+G38-J38 -> 0 | M38: =+L38*H38 -> 0
F39: FUNCIONAMIENTO Y OPERACIÓN DE RETROEXCAVADORA CATERPILLAR 416 E | G39: 0 | H39: 325000 | I39: =+G39*H39 -> 0 | J39: 0 | K39: =+J39*H39 -> 0 | L39: 0 | M39: =+L39*H39 -> 0
H40: SUBTOTAL | I40: =SUM(I36:I39) -> 0 | K40: =SUM(K36:K39) -> 0 | M40: =SUM(M36:M39) -> 0
A41: 7 | F41: FUNCIONAMIENTO Y OPERACIÓN DE BULLDOZER SOBRE ORUGA CATERPILLAR D6K XL | G41: 0 | H41: 443300 | I41: =+G41*H41 -> 0 | J41: 0 | K41: =+J41*H41 -> 0 | L41: 0 | M41: =+L41*H41 -> 0 | N41: INFORMACION ENTREGADA POR RIESGOS MUNICIPAL NO SE HA HECHO VISITA
F42: FUNCIONAMIENTO Y OPERACIÓN DE EXCAVADORA SOBRE ORUGA LINK-BELT 210 X2 | G42: 0 | H42: 460400 | I42: =+G42*H42 -> 0 | J42: 0 | K42: =+J42*H42 -> 0 | L42: =+G42-J42 -> 0 | M42: =+L42*H42 -> 0
...

Sheet PLAN con otrs puntos Vcio
C2: PLAN DE INTERVENCIÓN ESPECIFICO
D3: CONTRATO No. | F3: OBJETO: SERVICIO PARA LA OPERACIÓN DE LA MAQUINARIA AMARILLA ADSCRITA A LA DIRECCIÓN DEPARTAMENTAL PARA LA GESTIÓN DEL RIESGO DE DESASTRES PARA LA REDUCCIÓN DEL RIESGO EN LOS VEINTINUEVE (29) MUNICIPIOS DEL DEPARTAMENTO DEL META.
C4: PRESUPUESTO OPERACIÓN MAQUINARIA: | F4: 671921001 | G4: FECHA DE INICIO: | J4: FECHA DIA QUE SE ACTUALIZO:
C5: VALOR TOTAL CONTRATO INCLUYE IVA: | F5: =+F4*1.19 -> 7.9958599e+08 | G5: FECHA TERMINACIÓN: | J5: SUPERVISOR: | N5: APOYO A LA SUPERVISION:
A7: CONTRATO INICIAL
A8: N° PUNTO | B8: MUNICIPIO | C8: ZONA ESPECIFICA | D8: ACCIONES A REALIZAR | E8: RIESGO DE UN POSIBLE DESASTRE NATURAL O CALAMIDAD PUBLICA | F8: HORAS PROYECTADAS | J8: HORAS EJECUTADAS | L8: HORAS PROGRAMADAS | N8: OBSERVACIONES | O8: COORDINADOR DIGERD
F9: TIPO DE MAQUINA | G9: CANT. HORAS | H9: VALOR UNITARIO | I9: VALOR ($) | J9: CANT. HORAS | K9: VALOR ($) | L9: CANT. HORAS | M9: VALOR ($)
A10: 1 | B10: EL CALVARIO | C10: VEREDA EL CARMEN 73°43'48.51"O 4°20'41.81"N | D10: REHABILITACION PUNTOS CRÍTICOS VIA TERCIARIA. | E10: DERRUMBES, AFECTACIÓN DE LA VIA | F10: FUNCIONAMIENTO Y OPERACIÓN DE BULLDOZER SOBRE ORUGA CATERPILLAR D6K XL | G10: 75 | H10: 443300 | I10: =+G10*H10 -> 33247500 | J10: 0 | K10: =+J10*H10 -> 0 | L10: =+G10-J10 -> 75 | M10: =+L10*H10 -> 33247500 | N10: DE LAS 100 HORAS DE BULLDOZER ASIGNADAS AL PUNTO; 75 HORAS SE USARAN PARA LA INTERVENCIÓN, LAS CUALES INCLUYEN EL DESPLAZAMIENTO DE LA MAQUINA DESDE EL PUNTO ACTUAL DE PARQUEO HASTA EL PUNTO DE TRABAJO. LAS 25 HORAS RESTANTES SE DESTINAN PARA QUE EL BULLDOZER SE TRASLADE POR SUS PROPIOS MEDIOS HASTA EL SITIO MONTEREDONDO DONDE SERÁ RECOGIDO POR EL TRACTO CAMIÓN CAMABAJA. UNA VEZ FINALIZA LA INTERVENCIÓN LA MAQUINA UTILIZARA 25 HORAS PARA DESPLAZARCE DESDE EL PUNTO DE TRABAJO HASTA EL PUNTO DE EMBARCACIÓN A LA CAMA BAJA. | Q10: =+G10+G16+G21+G26+G31+G36+G41+G46+G11 -> 100
F11: FUNCIONAMIENTO Y OPERACIÓN DE BULLDOZER SOBRE ORUGA CATERPILLAR D6K XL | G11: 25 | H11: 443300 | I11: =+G11*H11 -> 11082500 | J11: 0 | K11: =+J11*H11 -> 0 | L11: =+G11-J11 -> 25 | M11: =+L11*H11 -> 11082500
F12: FUNCIONAMIENTO Y OPERACIÓN DE EXCAVADORA SOBRE ORUGA LINK-BELT 210 X2 | G12: 0 | H12: 460400 | I12: =+G12*H12 -> 0 | J12: 0 | K12: =+J12*H12 -> 0 | L12: 0 | M12: =+L12*H12 -> 0 | Q12: =+G12+G17+G22+G27+G32+G42+G47+G37 -> 867
F13: FUNCIONAMIENTO Y OPERACIÓN DE VOLQUETA SENCILLA FTR CHEVROLET | G13: 0 | H13: 278400 | I13: =+G13*H13 -> 0 | J13: 0 | K13: =+J13*H13 -> 0 | L13: 0 | M13: =+L13*H13 -> 0 | Q13: =+G13+G18+G23+G28+G33+G38+G43+G48 -> 150
F14: FUNCIONAMIENTO Y OPERACIÓN DE RETROEXCAVADORA CATERPILLAR 416 E | G14: 0 | H14: 325000 | I14: =+G14*H14 -> 0 | J14: 0 | K14: =+J14*H14 -> 0 | L14: 0 | M14: =+L14*H14 -> 0 | Q14: =+G14+G19+G24+G29+G34+G39+G44+G49 -> 0
H15: SUBTOTAL | I15: =SUM(I10:I14) -> 44330000 | K15: =SUM(K10:K14) -> 0 | M15: =SUM(M10:M14) -> 44330000
A16: 2 | B16: GUAMAL | C16: PIO XII 73°48'9.28"O 3°54'14.01"N | D16: DESCOLMATACIÓN, ENCAUZAMIENTO O CONFORMACIÓN DE JARILLONES | E16: DESBORDAMIENTO E INUNDACIÓN | F16: FUNCIONAMIENTO Y OPERACIÓN DE BULLDOZER SOBRE ORUGA CATERPILLAR D6K XL | G16: 0 | H16: 443300 | I16: =+G16*H16 -> 0 | J16: 0 | K16: =+J16*H16 -> 0 | L16: 0 | M16: =+L16*H16 -> 0 | N16: LAS 200 HORAS ASIGNADAS SON INSUFICIENTES PARA ATENDER ADECUADAMENTE LA AFECTACIÓN POR DESBORADAMIENTO E INUNDACIÓN DEL RIO GUAMAL EN EL SECTOR PIO XII, YA QUE SON MÁS DE 2 BRAZOS DEL RÍO QUE ATACAN LA MARGEN IZQUIERDA DEL RÍO GUAMAL LO QUE REQUIERE CONTAR CON HORAS SUFICIENTE PARA EJECUTAR LOS TRABAJOS AGUAS ARRIBA DE MANERA EFICIENTE.
F17: FUNCIONAMIENTO Y OPERACIÓN DE EXCAVADORA SOBRE ORUGA LINK-BELT 210 X2 | G17: 200 | H17: 460400 | I17: =+G17*H17 -> 92080000 | J17: 0 | K17: =+J17*H17 -> 0 | L17: =+G17-J17 -> 200 | M17: =+L17*H17 -> 92080000
F18: FUNCIONAMIENTO Y OPERACIÓN DE VOLQUETA SENCILLA FTR CHEVROLET | G18: 0 | H18: 278400 | I18: =+G18*H18 -> 0 | J18: 0 | K18: =+J18*H18 -> 0 | L18: 0 | M18: =+L18*H18 -> 0
F19: FUNCIONAMIENTO Y OPERACIÓN DE RETROEXCAVADORA CATERPILLAR 416 E | G19: 0 | H19: 325000 | I19: =+G19*H19 -> 0 | J19: 0 | K19: =+J19*H19 -> 0 | L19: 0 | M19: =+L19*H19 -> 0
H20: SUBTOTAL | I20: =SUM(I16:I19) -> 92080000 | K20: =SUM(K16:K19) -> 0 | M20: =SUM(M16:M19) -> 92080000
A21: 3 | B21: GRANADA | C21: PUENTE CAÑO URICHARE 73°43'35.18"O 3°25'3.11"N | D21: DESCOLMATACIÓN, ENCAUZAMIENTO O CONFORMACIÓN DE JARILLONES | E21: DESBORDAMIENTO E INUNDACIÓN | F21: FUNCIONAMIENTO Y OPERACIÓN DE BULLDOZER SOBRE ORUGA CATERPILLAR D6K XL | G21: 0 | H21: 443300 | I21: =+G21*H21 -> 0 | J21: 0 | K21: =+J21*H21 -> 0 | L21: 0 | M21: =+L21*H21 -> 0 | N21: EL MUNICIPIO DE GRANADA REQUIERE HACER CONCERTACIÓN CON EL INVIAS PARA DETERMINAR EL TIPO ESPECÍFICO DE TRABAJO EN LA ZONA DE INFLUENCIA DEL PUENTE
F22: FUNCIONAMIENTO Y OPERACIÓN DE EXCAVADORA SOBRE ORUGA LINK-BELT 210 X2 | G22: 100 | H22: 460400 | I22: =+G22*H22 -> 46040000 | J22: 0 | K22: =+J22*H22 -> 0 | L22: =+G22-J22 -> 100 | M22: =+L22*H22 -> 46040000
F23: FUNCIONAMIENTO Y OPERACIÓN DE VOLQUETA SENCILLA FTR CHEVROLET | G23: 0 | H23: 278400 | I23: =+G23*H23 -> 0 | J23: 0 | K23: =+J23*H23 -> 0 | L23: 0 | M23: =+L23*H23 -> 0
F24: FUNCIONAMIENTO Y OPERACIÓN DE RETROEXCAVADORA CATERPILLAR 416 E | G24: 0 | H24: 325000 | I24: =+G24*H24 -> 0 | J24: 0 | K24: =+J24*H24 -> 0 | L24: 0 | M24: =+L24*H24 -> 0
H25: SUBTOTAL | I25: =SUM(I21:I24) -> 46040000 | K25: =SUM(K21:K24) -> 0 | M25: =SUM(M21:M24) -> 46040000
A26: 4 | B26: VILLAVICENCIO | C26: PALMARITO ARRAYANES 73°19'6.96"O 3°57'54.72"N | D26: DESCOLMATACIÓN, ENCAUZAMIENTO O CONFORMACIÓN DE JARILLONES | E26: DESBORDAMIENTO E INUNDACIÓN | F26: FUNCIONAMIENTO Y OPERACIÓN DE BULLDOZER SOBRE ORUGA CATERPILLAR D6K XL | G26: 0 | H26: 443300 | I26: =+G26*H26 -> 0 | J26: 0 | K26: =+J26*H26 -> 0 | L26: 0 | M26: =+L26*H26 -> 0 | N26: LA MAGNITUD DE AFECTACIÓN DE ESTE PUNTO ES MUY GRANDE POR LO QUE SE REQUIERE INICIAR INTERVENCIÓN EN ÉPOCAS EN LA QUE EL RÍO HAYA BAJADO SU NIVEL
F27: FUNCIONAMIENTO Y OPERACIÓN DE EXCAVADORA SOBRE ORUGA LINK-BELT 210 X2 | G27: 250 | H27: 460400 | I27: =+G27*H27 -> 115100000 | J27: 0 | K27: =+J27*H27 -> 0 | L27: =+G27-J27 -> 250 | M27: =+L27*H27 -> 115100000
F28: FUNCIONAMIENTO Y OPERACIÓN DE VOLQUETA SENCILLA FTR CHEVROLET | G28: 0 | H28: 278400 | I28: =+G28*H28 -> 0 | J28: 0 | K28: =+J28*H28 -> 0 | L28: 0 | M28: =+L28*H28 -> 0
F29: FUNCIONAMIENTO Y OPERACIÓN DE RETROEXCAVADORA CATERPILLAR 416 E | G29: 0 | H29: 325000 | I29: =+G29*H29 -> 0 | J29: 0 | K29: =+J29*H29 -> 0 | L29: 0 | M29: =+L29*H29 -> 0
H30: SUBTOTAL | I30: =SUM(I26:I29) -> 115100000 | K30: =SUM(K26:K29) -> 0 | M30: =SUM(M26:M29) -> 115100000
A31: 5 | B31: VILLAVICENCIO | C31: VEREDA LA ARGENTINA | D31: DESCOLMATACIÓN, ENCAUZAMIENTO O CONFORMACIÓN DE JARILLONES | E31: DESBORDAMIENTO E INUNDACIÓN | F31: FUNCIONAMIENTO Y OPERACIÓN DE BULLDOZER SOBRE ORUGA CATERPILLAR D6K XL | G31: 0 | H31: 443300 | I31: =+G31*H31 -> 0 | J31: 0 | K31: =+J31*H31 -> 0 | L31: 0 | M31: =+L31*H31 -> 0 | N31: INFORMACION ENTREGADA POR RIESGOS MUNICIPAL NO SE HA HECHO VISITA
F32: FUNCIONAMIENTO Y OPERACIÓN DE EXCAVADORA SOBRE ORUGA LINK-BELT 210 X2 | G32: 57 | H32: 460400 | I32: =+G32*H32 -> 26242800 | J32: 0 | K32: =+J32*H32 -> 0 | L32: =+G32-J32 -> 57 | M32: =+L32*H32 -> 26242800
F33: FUNCIONAMIENTO Y OPERACIÓN DE VOLQUETA SENCILLA FTR CHEVROLET | G33: 75 | H33: 278400 | I33: =+G33*H33 -> 20880000 | J33: 0 | K33: =+J33*H33 -> 0 | L33: =+G33-J33 -> 75 | M33: =+L33*H33 -> 20880000
F34: FUNCIONAMIENTO Y OPERACIÓN DE RETROEXCAVADORA CATERPILLAR 416 E | G34: 0 | H34: 325000 | I34: =+G34*H34 -> 0 | J34: 0 | K34: =+J34*H34 -> 0 | L34: 0 | M34: =+L34*H34 -> 0
H35: SUBTOTAL | I35: =SUM(I31:I34) -> 47122800 | K35: =SUM(K31:K34) -> 0 | M35: =SUM(M31:M34) -> 47122800
A36: 6 | B36: VILLAVICENCIO | C36: QUINTAS DEL LLANO | D36: DESCOLMATACIÓN, ENCAUZAMIENTO O CONFORMACIÓN DE JARILLONES | E36: DESBORDAMIENTO E INUNDACIÓN | F36: FUNCIONAMIENTO Y OPERACIÓN DE BULLDOZER SOBRE ORUGA CATERPILLAR D6K XL | G36: 0 | H36: 443300 | I36: =+G36*H36 -> 0 | J36: 0 | K36: =+J36*H36 -> 0 | L36: 0 | M36: =+L36*H36 -> 0 | N36: INFORMACION ENTREGADA POR RIESGOS MUNICIPAL NO SE HA HECHO VISITA
F37: FUNCIONAMIENTO Y OPERACIÓN DE EXCAVADORA SOBRE ORUGA LINK-BELT 210 X2 | G37: 100 | H37: 460400 | I37: =+G37*H37 -> 46040000 | J37: 0 | K37: =+J37*H37 -> 0 | L37: =+G37-J37 -> 100 | M37: =+L37*H37 -> 46040000
F38: FUNCIONAMIENTO Y OPERACIÓN DE VOLQUETA SENCILLA FTR CHEVROLET | G38: 75 | H38: 278400 | I38: =+G38*H38 -> 20880000 | J38: 0 | K38: =+J38*H38 -> 0 | L38: =+G38-J38 -> 75 | M38: =+L38*H38 -> 20880000
F39: FUNCIONAMIENTO Y OPERACIÓN DE RETROEXCAVADORA CATERPILLAR 416 E | G39: 0 | H39: 325000 | I39: =+G39*H39 -> 0 | J39: 0 | K39: =+J39*H39 -> 0 | L39: 0 | M39: =+L39*H39 -> 0
H40: SUBTOTAL | I40: =SUM(I36:I39) -> 66920000 | K40: =SUM(K36:K39) -> 0 | M40: =SUM(M36:M39) -> 66920000
A41: 7 | B41: VILLAVICENCIO | C41: BRISAS DE APIAY | D41: DESCOLMATACIÓN, ENCAUZAMIENTO O CONFORMACIÓN DE JARILLONES | E41: DESBORDAMIENTO E INUNDACIÓN | F41: FUNCIONAMIENTO Y OPERACIÓN DE BULLDOZER SOBRE ORUGA CATERPILLAR D6K XL | G41: 0 | H41: 443300 | I41: =+G41*H41 -> 0 | J41: 0 | K41: =+J41*H41 -> 0 | L41: 0 | M41: =+L41*H41 -> 0 | N41: INFORMACION ENTREGADA POR RIESGOS MUNICIPAL NO SE HA HECHO VISITA
F42: FUNCIONAMIENTO Y OPERACIÓN DE EXCAVADORA SOBRE ORUGA LINK-BELT 210 X2 | G42: 80 | H42: 460400 | I42: =+G42*H42 -> 36832000 | J42: 0 | K42: =+J42*H42 -> 0 | L42: =+G42-J42 -> 80 | M42: =+L42*H42 -> 36832000
...

Sheet PLAN DE ACCIÓN
C2: PLAN DE INTERVENCIÓN ESPECIFICO
C3: CONTRATO No. | E3: OBJETO:
C4: PRESUPUESTO OPERACIÓN MAQUINARIA: | F4: 671921001 | G4: FECHA DE INICIO: | I4: 45755 | J4: SUPERVISOR:
C5: VALOR TOTAL CONTRATO INCLUYE IVA: | F5: =+F4*1.19 -> 7.9958599e+08 | G5: FECHA TERMINACIÓN: | I5: 45815 | J5: APOYO A LA SUPERVISIÓN: | N5: APOYO A LA SUPERVISION:
G6: FECHA DE ACTUALIZACIÓN: | I6: 45858
A8: CONTRATO INICIAL
A9: N° PUNTO | B9: MUNICIPIO | C9: ZONA ESPECIFICA | D9: ACCIONES A REALIZAR | E9: RIESGO DE UN POSIBLE DESASTRE NATURAL O CALAMIDAD PUBLICA | F9: HORAS PROYECTADAS | J9: HORAS EJECUTADAS | L9: HORAS POR EJECUTAR | N9: OBSERVACIONES | O9: COORDINADOR DIGERD
F10: TIPO DE MAQUINA | G10: CANT. HORAS | H10: VALOR UNITARIO | I10: VALOR ($) | J10: CANT. HORAS | K10: VALOR ($) | L10: CANT. HORAS | M10: VALOR ($)
A11: 1 | B11: EL CALVARIO | C11: VEREDA EL CARMEN Y VEREDA SAN BERNARDO 73°43'48.51"O 4°20'41.81"N | D11: REHABILITACION PUNTOS CRÍTICOS VIA TERCIARIA. | E11: DERRUMBES, AFECTACIÓN DE LA VIA | F11: FUNCIONAMIENTO Y OPERACIÓN DE BULLDOZER SOBRE ORUGA CATERPILLAR D6K XL | G11: 0 | H11: 0 | I11: =+G11*H11 -> 0 | J11: 0 | K11: =+J11*H11 -> 0 | L11: =+G11-J11 -> 0 | M11: =+L11*H11 -> 0 | N11: DE LAS 100 HORAS DE BULLDOZER ASIGNADAS AL PUNTO; 75 HORAS SE USARAN PARA LA INTERVENCIÓN, LAS CUALES INCLUYEN EL DESPLAZAMIENTO DE LA MAQUINA DESDE EL PUNTO ACTUAL DE PARQUEO HASTA EL PUNTO DE TRABAJO. LAS 25 HORAS RESTANTES SE DESTINAN PARA QUE EL BULLDOZER SE TRASLADE POR SUS PROPIOS MEDIOS HASTA EL SITIO MONTEREDONDO DONDE SERÁ RECOGIDO POR EL TRACTO CAMIÓN CAMABAJA. UNA VEZ FINALIZA LA INTERVENCIÓN LA MAQUINA UTILIZARA 25 HORAS PARA DESPLAZARCE DESDE EL PUNTO DE TRABAJO HASTA EL PUNTO DE EMBARCACIÓN A LA CAMA BAJA.
F12: FUNCIONAMIENTO Y OPERACIÓN DE EXCAVADORA SOBRE ORUGA LINK-BELT 210 X2 | G12: 0 | H12: 0 | I12: =+G12*H12 -> 0 | J12: 0 | K12: =+J12*H12 -> 0 | L12: 0 | M12: =+L12*H12 -> 0
F13: FUNCIONAMIENTO Y OPERACIÓN DE VOLQUETA SENCILLA FTR CHEVROLET | G13: 0 | H13: 0 | I13: =+G13*H13 -> 0 | J13: 0 | K13: =+J13*H13 -> 0 | L13: 0 | M13: =+L13*H13 -> 0
F14: FUNCIONAMIENTO Y OPERACIÓN DE RETROEXCAVADORA CATERPILLAR 416 E | G14: 0 | H14: 0 | I14: =+G14*H14 -> 0 | J14: 0 | K14: =+J14*H14 -> 0 | L14: 0 | M14: =+L14*H14 -> 0
H15: SUBTOTAL | I15: =SUM(I11:I14) -> 0 | K15: =SUM(K11:K14) -> 0 | M15: =SUM(M11:M14) -> 0
A16: 2 | C16: VIA VILLAVICENCIO - MONFORTH 73°38'26.11"O 4°19'17.70"N | D16: DESCOLMATACIÓN, ENCAUZAMIENTO O CONFORMACIÓN DE JARILLONES | E16: DESBORDAMIENTO E INUNDACIÓN | F16: FUNCIONAMIENTO Y OPERACIÓN DE BULLDOZER SOBRE ORUGA CATERPILLAR D6K XL | H16: 0 | I16: =+G16*H16 -> 0 | J16: 0 | K16: =+J16*H16 -> 0 | L16: =+G16-J16 -> 0 | M16: =+L16*H16 -> 0 | N16: INFORMACION ENTREGADA POR RIESGOS MUNICIPAL NO SE HA HECHO VISITA
F17: FUNCIONAMIENTO Y OPERACIÓN DE EXCAVADORA SOBRE ORUGA LINK-BELT 210 X2 | H17: 0 | I17: =+G17*H17 -> 0 | J17: 0 | K17: =+J17*H17 -> 0 | L17: =+G17-J17 -> 0 | M17: =+L17*H17 -> 0
F18: FUNCIONAMIENTO Y OPERACIÓN DE VOLQUETA SENCILLA FTR CHEVROLET | H18: 0 | I18: =+G18*H18 -> 0 | J18: 0 | K18: =+J18*H18 -> 0 | L18: =+G18-J18 -> 0 | M18: =+L18*H18 -> 0
F19: FUNCIONAMIENTO Y OPERACIÓN DE RETROEXCAVADORA CATERPILLAR 416 E | G19: 0 | H19: 0 | I19: =+G19*H19 -> 0 | J19: 0 | K19: =+J19*H19 -> 0 | L19: =+G19-J19 -> 0 | M19: =+L19*H19 -> 0
H20: SUBTOTAL | I20: =SUM(I16:I19) -> 0 | K20: =SUM(K16:K19) -> 0 | M20: =SUM(M16:M19) -> 0
A21: 3 | B21: GUAMAL | C21: PIO XII 73°48'9.28"O 3°54'14.01"N | D21: DESCOLMATACIÓN, ENCAUZAMIENTO O CONFORMACIÓN DE JARILLONES | E21: DESBORDAMIENTO E INUNDACIÓN | F21: FUNCIONAMIENTO Y OPERACIÓN DE BULLDOZER SOBRE ORUGA CATERPILLAR D6K XL | G21: 0 | H21: 0 | I21: =+G21*H21 -> 0 | J21: 0 | K21: =+J21*H21 -> 0 | L21: 0 | M21: =+L21*H21 -> 0 | N21: LAS 200 HORAS ASIGNADAS SON INSUFICIENTES PARA ATENDER ADECUADAMENTE LA AFECTACIÓN POR DESBORADAMIENTO E INUNDACIÓN DEL RIO GUAMAL EN EL SECTOR PIO XII, YA QUE SON MÁS DE 2 BRAZOS DEL RÍO QUE ATACAN LA MARGEN IZQUIERDA DEL RÍO GUAMAL LO QUE REQUIERE CONTAR CON HORAS SUFICIENTE PARA EJECUTAR LOS TRABAJOS AGUAS ARRIBA DE MANERA EFICIENTE.
F22: FUNCIONAMIENTO Y OPERACIÓN DE EXCAVADORA SOBRE ORUGA LINK-BELT 210 X2 | G22: 130 | H22: 0 | I22: =+G22*H22 -> 0 | J22: 0 | K22: =+J22*H22 -> 0 | L22: 0 | M22: =+L22*H22 -> 0
F23: FUNCIONAMIENTO Y OPERACIÓN DE VOLQUETA SENCILLA FTR CHEVROLET | G23: 0 | H23: 0 | I23: =+G23*H23 -> 0 | J23: 0 | K23: =+J23*H23 -> 0 | L23: 0 | M23: =+L23*H23 -> 0
F24: FUNCIONAMIENTO Y OPERACIÓN DE RETROEXCAVADORA CATERPILLAR 416 E | G24: 0 | H24: 0 | I24: =+G24*H24 -> 0 | J24: 0 | K24: =+J24*H24 -> 0 | L24: 0 | M24: =+L24*H24 -> 0
H25: SUBTOTAL | I25: =SUM(I21:I24) -> 0 | K25: =SUM(K21:K24) -> 0 | M25: =SUM(M21:M24) -> 0
A26: 4 | C26: SECTOR LA ISLA 73°48'54.35"O 3°54'18.38"N 73°49'38.21"O 3°54'34.58"N | D26: DESCOLMATACIÓN, ENCAUZAMIENTO O CONFORMACIÓN DE JARILLONES | E26: DESBORDAMIENTO E INUNDACIÓN | F26: FUNCIONAMIENTO Y OPERACIÓN DE BULLDOZER SOBRE ORUGA CATERPILLAR D6K XL | G26: 0 | H26: 0 | I26: =+G26*H26 -> 0 | J26: 0 | K26: =+J26*H26 -> 0 | L26: 0 | M26: =+L26*H26 -> 0 | N26: LAS 200 HORAS ASIGNADAS SON INSUFICIENTES PARA ATENDER ADECUADAMENTE LA AFECTACIÓN POR DESBORADAMIENTO E INUNDACIÓN DEL RIO GUAMAL EN EL SECTOR PIO XII, YA QUE SON MÁS DE 2 BRAZOS DEL RÍO QUE ATACAN LA MARGEN IZQUIERDA DEL RÍO GUAMAL LO QUE REQUIERE CONTAR CON HORAS SUFICIENTE PARA EJECUTAR LOS TRABAJOS AGUAS ARRIBA DE MANERA EFICIENTE.
F27: FUNCIONAMIENTO Y OPERACIÓN DE EXCAVADORA SOBRE ORUGA LINK-BELT 210 X2 | G27: =70+200 -> 270 | H27: 0 | I27: =+G27*H27 -> 0 | J27: 0 | K27: =+J27*H27 -> 0 | L27: 0 | M27: =+L27*H27 -> 0
F28: FUNCIONAMIENTO Y OPERACIÓN DE VOLQUETA SENCILLA FTR CHEVROLET | G28: 0 | H28: 0 | I28: =+G28*H28 -> 0 | J28: 0 | K28: =+J28*H28 -> 0 | L28: 0 | M28: =+L28*H28 -> 0
F29: FUNCIONAMIENTO Y OPERACIÓN DE RETROEXCAVADORA CATERPILLAR 416 E | G29: 0 | H29: 0 | I29: =+G29*H29 -> 0 | J29: 0 | K29: =+J29*H29 -> 0 | L29: 0 | M29: =+L29*H29 -> 0
H30: SUBTOTAL | I30: =SUM(I26:I29) -> 0 | K30: =SUM(K26:K29) -> 0 | M30: =SUM(M26:M29) -> 0
A31: 6 | B31: VILLAVICENCIO | C31: PALMARITO ARRAYANES 73°19'6.96"O 3°57'54.72"N | D31: DESCOLMATACIÓN, ENCAUZAMIENTO O CONFORMACIÓN DE JARILLONES | E31: DESBORDAMIENTO E INUNDACIÓN | F31: FUNCIONAMIENTO Y OPERACIÓN DE BULLDOZER SOBRE ORUGA CATERPILLAR D6K XL | G31: 0 | H31: 0 | I31: =+G31*H31 -> 0 | J31: 0 | K31: =+J31*H31 -> 0 | L31: 0 | M31: =+L31*H31 -> 0 | N31: LA MAGNITUD DE AFECTACIÓN DE ESTE PUNTO ES MUY GRANDE POR LO QUE SE REQUIERE INICIAR INTERVENCIÓN EN ÉPOCAS EN LA QUE EL RÍO HAYA BAJADO SU NIVEL
F32: FUNCIONAMIENTO Y OPERACIÓN DE EXCAVADORA SOBRE ORUGA LINK-BELT 210 X2 | G32: 0 | H32: 0 | I32: =+G32*H32 -> 0 | J32: 0 | K32: =+J32*H32 -> 0 | L32: =+G32-J32 -> 0 | M32: =+L32*H32 -> 0
F33: FUNCIONAMIENTO Y OPERACIÓN DE VOLQUETA SENCILLA FTR CHEVROLET | G33: 0 | H33: 0 | I33: =+G33*H33 -> 0 | J33: 0 | K33: =+J33*H33 -> 0 | L33: 0 | M33: =+L33*H33 -> 0
F34: FUNCIONAMIENTO Y OPERACIÓN DE RETROEXCAVADORA CATERPILLAR 416 E | G34: 0 | H34: 0 | I34: =+G34*H34 -> 0 | J34: 0 | K34: =+J34*H34 -> 0 | L34: 0 | M34: =+L34*H34 -> 0
H35: SUBTOTAL | I35: =SUM(I31:I34) -> 0 | K35: =SUM(K31:K34) -> 0 | M35: =SUM(M31:M34) -> 0
A36: 7 | C36: PARCELAS DEL PROGRESO | D36: DESCOLMATACIÓN, ENCAUZAMIENTO O CONFORMACIÓN DE JARILLONES | E36: DESBORDAMIENTO E INUNDACIÓN | F36: FUNCIONAMIENTO Y OPERACIÓN DE BULLDOZER SOBRE ORUGA CATERPILLAR D6K XL | H36: 0 | I36: =+G36*H36 -> 0 | J36: 0 | K36: =+J36*H36 -> 0 | L36: =+G36-J36 -> 0 | M36: =+L36*H36 -> 0 | N36: INFORMACION ENTREGADA POR RIESGOS MUNICIPAL NO SE HA HECHO VISITA
F37: FUNCIONAMIENTO Y OPERACIÓN DE EXCAVADORA SOBRE ORUGA LINK-BELT 210 X2 | H37: 0 | I37: =+G37*H37 -> 0 | J37: 0 | K37: =+J37*H37 -> 0 | L37: =+G37-J37 -> 0 | M37: =+L37*H37 -> 0
F38: FUNCIONAMIENTO Y OPERACIÓN DE VOLQUETA SENCILLA FTR CHEVROLET | G38: 0 | H38: 0 | I38: =+G38*H38 -> 0 | J38: 0 | K38: =+J38*H38 -> 0 | L38: =+G38-J38 -> 0 | M38: =+L38*H38 -> 0
F39: FUNCIONAMIENTO Y OPERACIÓN DE RETROEXCAVADORA CATERPILLAR 416 E | H39: 0 | I39: =+G39*H39 -> 0 | J39: 0 | K39: =+J39*H39 -> 0 | L39: =+G39-J39 -> 0 | M39: =+L39*H39 -> 0
H40: SUBTOTAL | I40: =SUM(I36:I39) -> 0 | K40: =SUM(K36:K39) -> 0 | M40: =SUM(M36:M39) -> 0
A41: 8 | B41: EL CASTILLO, EL DORADO | C41: TRASVASE DE RIO ARIARI A RIO VIEJO | D41: DESCOLMATACIÓN, ENCAUZAMIENTO O CONFORMACIÓN DE JARILLONES | E41: DESBORDAMIENTO E INUNDACIÓN | F41: FUNCIONAMIENTO Y OPERACIÓN DE BULLDOZER SOBRE ORUGA CATERPILLAR D6K XL | H41: 0 | I41: =+G41*H41 -> 0 | J41: 0 | K41: =+J41*H41 -> 0 | L41: =+G41-J41 -> 0 | M41: =+L41*H41 -> 0 | N41: INFORMACION ENTREGADA POR RIESGOS MUNICIPAL NO SE HA HECHO VISITA
F42: FUNCIONAMIENTO Y OPERACIÓN DE EXCAVADORA SOBRE ORUGA LINK-BELT 210 X2 | G42: 0 | H42: 0 | I42: =+G42*H42 -> 0 | J42: 0 | K42: =+J42*H42 -> 0 | L42: =+G42-J42 -> 0 | M42: =+L42*H42 -> 0
...

Sheet RESUMEN
A1: RESUMEN GENERAL DE ACTIVIDADES EJECUTADAS
A2: CONTRATO Nº:
A3: OBJETO:
A4: PERIODO DEL INFORME: | F4: AL
A5: FECHA PRESENTE ACTA:
A8: ITEM | B8: DESCRIPCIÓN / MAQUINA | C8: MUNICIPIO | D8: PUNTO | E8: FECHA INICIO | F8: FECHA FINAL | G8: HORAS EJECUTADAS | H8: VALOR EJECUTADO | I8: ACTIVIDAD REALIZADA
A9: 1 | B9: FUNCIONAMIENTO Y OPERACIÓN DE TRACTO-CAMIÓN INTERNACIONAL 7600 CAPACIDAD CARGA 35 TONELADAS CON ACCESORIO CAMABAJA
B10: =+'CAMABAJA OJT166'!C6 -> CAMABAJA INTERNATIONAL OJT166 | C10: =+'CAMABAJA OJT166'!C10 -> VILLAVICENCIO - PATIO GALICIA SERVIMACONS | D10: =+'CAMABAJA OJT166'!D10 -> BAJO POMPEYA SECTOR PALMARITO, RIO GUAYURIBA | E10: =+'CAMABAJA OJT166'!B10 -> 45755 | F10: =+'CAMABAJA OJT166'!B10 -> 45755 | G10: =+'CAMABAJA OJT166'!H10 -> 4 | H10: =+G10*'PLAN DE ACCIÓN'!$H$51 -> 0 | I10: =+'CAMABAJA OJT166'!I10 -> NOS DIRIJIMOS DEL MUNICIPIO DE VILLAVICENCIO PARA TRANSPORTAR LA EXCAVADORA LINK BELT 2181 #1 DEL PATIO GALICIA SERVIMACONS PARA EL PUNTO DE TRABAJO BAJO POMPEYA SECTOR PALMARITO, RIO GUAYURIBA Y NOS REGRESAMOS AL PATIO SERVIMACONS
C11: =+'CAMABAJA OJT166'!C11 -> VILLAVICENCIO - PATIO GALICIA SERVIMACONS | D11: =+'CAMABAJA OJT166'!D11 -> BAJO POMPEYA SECTOR PALMARITO, RIO GUAYURIBA | E11: =+'CAMABAJA OJT166'!B11 -> 45755 | F11: =+'CAMABAJA OJT166'!B11 -> 45755 | G11: =+'CAMABAJA OJT166'!H11 -> 4 | H11: =+G11*'PLAN DE ACCIÓN'!$H$51 -> 0 | I11: =+'CAMABAJA OJT166'!I11 -> NOS DIRIJIMOS DEL MUNICIPIO DE VILLAVICENCIO PARA TRANSPORTAR LA EXCAVADORA LINK BELT 2180 #5 DEL PATIO GALICIA SERVIMACONS PARA EL PUNTO DE TRABAJO BAJO POMPEYA SECTOR PALMARITO, RIO GUAYURIBA Y NOS REGRESAMOS AL PATIO SERVIMACONS
C12: =+'CAMABAJA OJT166'!C12 -> VILLAVICENCIO - PATIO GALICIA SERVIMACONS | D12: =+'CAMABAJA OJT166'!D12 -> SECTOR LA ISLA, RIO GUAMAL | E12: =+'CAMABAJA OJT166'!B12 -> 45756 | F12: =+'CAMABAJA OJT166'!B12 -> 45756 | G12: =+'CAMABAJA OJT166'!H12 -> 8 | H12: =+G12*'PLAN DE ACCIÓN'!$H$51 -> 0 | I12: =+'CAMABAJA OJT166'!I12 -> NOS DIRIJIMOS DEL MUNICIPIO DE VILLAVICENCIO PARA TRANSPORTAR LA EXCAVADORA LINK BELT 2183 #3 DEL PATIO GALICIA SERVIMACONS PARA EL PUNTO DE TRABAJO SECTOR LA ISLA RIO GUAMAL Y NOS REGRESAMOS AL PATIO SERVIMACONS
C13: =+'CAMABAJA OJT166'!C13 -> VILLAVICENCIO - PATIO GALICIA SERVIMACONS | D13: =+'CAMABAJA OJT166'!D13 -> SECTOR PIO XII, RIO GUAMAL | E13: =+'CAMABAJA OJT166'!B13 -> 45757 | F13: =+'CAMABAJA OJT166'!B13 -> 45757 | G13: =+'CAMABAJA OJT166'!H13 -> 4 | H13: =+G13*'PLAN DE ACCIÓN'!$H$51 -> 0 | I13: =+'CAMABAJA OJT166'!I13 -> NOS DIRIJIMOS DEL MUNICIPIO DE VILLAVICENCIO PARA TRANSPORTAR LA EXCAVADORA LINK BELT 2179 #4 DEL PATIO GALICIA SERVIMACONS PARA EL PUNTO DE TRABAJO SECTOR PIO XII RIO GUAMAL Y NOS REGRESAMOS AL PATIO SERVIMACONS
C14: =+'CAMABAJA OJT166'!C14 -> EL CALVARIO | D14: =+'CAMABAJA OJT166'!D14 -> VIA MONFORTH | E14: =+'CAMABAJA OJT166'!B14 -> 45770 | F14: =+'CAMABAJA OJT166'!B14 -> 45770 | G14: =+'CAMABAJA OJT166'!H14 -> 3 | H14: =+G14*'PLAN DE ACCIÓN'!$H$51 -> 0 | I14: =+'CAMABAJA OJT166'!I14 -> NOS DIRIJIMOS DEL MUNICIPIO DE VILLAVICENCIO PARA TRANSPORTAR LA RETROEXCAVADORA CATERPILLAR 8585 416E DEL PATIO GALICIA SERVIMACONS PARA LA VIA MONFORTH Y NOS REGRESAMOS AL PATIO SERVIMACONS
C15: =+'CAMABAJA OJT166'!C15 -> BAJO POMPEYA SECTOR PALMARITO, RIO GUAYURIBA | D15: =+'CAMABAJA OJT166'!D15 -> VILLAVICENCIO - PATIO GALICIA SERVIMACONS | E15: =+'CAMABAJA OJT166'!B15 -> 45777 | F15: =+'CAMABAJA OJT166'!B15 -> 45777 | G15: =+'CAMABAJA OJT166'!H15 -> 4 | H15: =+G15*'PLAN DE ACCIÓN'!$H$51 -> 0 | I15: =+'CAMABAJA OJT166'!I15 -> NOS DIRIJIMOS DEL MUNICIPIO DE VILLAVICENCIO PARA TRANSPORTAR LA EXCAVADORA LINK BELT 2181 #1 DEL PUNTO DE TRABAJO BAJO POMPEYA PARA EL PATIO GALICIA SERVIMACONS
C16: =+'CAMABAJA OJT166'!C16 -> BAJO POMPEYA SECTOR PALMARITO, RIO GUAYURIBA | D16: =+'CAMABAJA OJT166'!D16 -> VILLAVICENCIO - PATIO GALICIA SERVIMACONS | E16: =+'CAMABAJA OJT166'!B16 -> 45777 | F16: =+'CAMABAJA OJT166'!B16 -> 45777 | G16: =+'CAMABAJA OJT166'!H16 -> 4 | H16: =+G16*'PLAN DE ACCIÓN'!$H$51 -> 0 | I16: =+'CAMABAJA OJT166'!I16 -> NOS DIRIJIMOS DEL MUNICIPIO DE VILLAVICENCIO PARA TRANSPORTAR LA EXCAVADORA LINK BELT 2180 #5 DEL PUNTO DE TRABAJO BAJO POMPEYA PARA EL PATIO GALICIA SERVIMACONS
C17: =+'CAMABAJA OJT166'!C17 -> VILLAVICENCIO - PATIO GALICIA SERVIMACONS | D17: =+'CAMABAJA OJT166'!D17 -> EL DORADO, SECTOR LA ISLA RIO ARIARI | E17: =+'CAMABAJA OJT166'!B17 -> 45778 | F17: =+'CAMABAJA OJT166'!B17 -> 45778 | G17: =+'CAMABAJA OJT166'!H17 -> 5 | H17: =+G17*'PLAN DE ACCIÓN'!$H$51 -> 0 | I17: =+'CAMABAJA OJT166'!I17 -> NOS DIRIJIMOS DEL MUNICIPIO DE VILLAVICENCIO PARA TRANSPORTAR LA EXCAVADORA LINK BELT 2181 #1 DEL PATIO SERVIMACONS PARA EL PUNTO DE TRABAJO EL DORADO PUENTE LA AMISTAD Y NOS REGRESAMOS AL PATIO SERVIMACONS
C18: =+'CAMABAJA OJT166'!C18 -> VILLAVICENCIO - PATIO GALICIA SERVIMACONS | D18: =+'CAMABAJA OJT166'!D18 -> EL DORADO, SECTOR LA ISLA RIO ARIARI | E18: =+'CAMABAJA OJT166'!B18 -> 45784 | F18: =+'CAMABAJA OJT166'!B18 -> 45784 | G18: =+'CAMABAJA OJT166'!H18 -> 4 | H18: =+G18*'PLAN DE ACCIÓN'!$H$51 -> 0 | I18: =+'CAMABAJA OJT166'!I18 -> NOS DIRIJIMOS DEL MUNICIPIO DE VILLAVICENCIO PARA TRANSPORTAR LA EXCAVADORA LINK BELT 2180 #5 DEL PATIO GALICIA SERVIMACONS PARA EL PUNTO DE TRABAJO EL DORADO, SECTOR LA ISLA RIO ARIARI Y NOS DIRIJIMOS AL MUNICIPIO DE GUAMAL
C19: =+'CAMABAJA OJT166'!C19 -> VILLAVICENCIO - PATIO GALICIA SERVIMACONS | D19: =+'CAMABAJA OJT166'!D19 -> EL DORADO, SECTOR LA ISLA RIO ARIARI | E19: =+'CAMABAJA OJT166'!B19 -> 45784 | F19: =+'CAMABAJA OJT166'!B19 -> 45784 | G19: =+'CAMABAJA OJT166'!H19 -> 4 | H19: =+G19*'PLAN DE ACCIÓN'!$H$51 -> 0 | I19: =+'CAMABAJA OJT166'!I19 -> NOS DIRIJIMOS DEL MUNICIPIO DE VILLAVICENCIO PARA TRANSPORTAR LA EXCAVADORA LINK BELT 2179 #4 DEL PUNTO DE TRABAJO PIO XII PARA EL PUNTO DE TRABAJO EL DORARO SECTOR LA ISLA RIO ARIARI Y NOS REGRESAMOS AL PATIO SERVIMACONS
C20: =+'CAMABAJA OJT166'!C20 -> EL DORADO, SECTOR LA ISLA RIO ARIARI | D20: =+'CAMABAJA OJT166'!D20 -> SECTOR PUERTO ESPERANZA | E20: =+'CAMABAJA OJT166'!B20 -> 45794 | F20: =+'CAMABAJA OJT166'!B20 -> 45794 | G20: =+'CAMABAJA OJT166'!H20 -> 4 | H20: =+G20*'PLAN DE ACCIÓN'!$H$51 -> 0 | I20: =+'CAMABAJA OJT166'!I20 -> NOS DIRIJIMOS DEL MUNICIPIO DE VILLAVICENCIO PARA TRANSPORTAR LA EXCAVADORA LINK BELT 2179 #4 DEL PUNTO DE TRABAJO SECTOR LA ISLA RIO ARIARI PARA EL PUNTO PUERTO ESPERANZA Y NOS REGRESAMOS AL PATIO SERVIMACONS
C21: =+'CAMABAJA OJT166'!C21 -> GUAMAL, SECTOR LA ISLA RIO GUAMAL | D21: =+'CAMABAJA OJT166'!D21 -> VILLAVICENCIO - PATIO GALICIA SERVIMACONS | E21: =+'CAMABAJA OJT166'!B21 -> 45800 | F21: =+'CAMABAJA OJT166'!B21 -> 45800 | G21: =+'CAMABAJA OJT166'!H21 -> 4 | H21: =+G21*'PLAN DE ACCIÓN'!$H$51 -> 0 | I21: =+'CAMABAJA OJT166'!I21 -> NOS DIRIJIMOS DEL MUNICIPIO DE VILLAVICENCIO PARA TRANSPORTAR LA EXCAVADORA LINK BELT 2183 #3 DEL PUNTO DE TRABAJO GUAMAL, SECTOR LA ISLA RIO ARIARI Y NOS REGRESAMOS AL PATIO SERVIMACONS
C22: =+'CAMABAJA OJT166'!C22 -> EL DORADO, SECTOR LA ISLA RIO ARIARI | D22: =+'CAMABAJA OJT166'!D22 -> VILLAVICENCIO - PATIO GALICIA SERVIMACONS | E22: =+'CAMABAJA OJT166'!B22 -> 45801 | F22: =+'CAMABAJA OJT166'!B22 -> 45801 | G22: =+'CAMABAJA OJT166'!H22 -> 5 | H22: =+G22*'PLAN DE ACCIÓN'!$H$51 -> 0 | I22: =+'CAMABAJA OJT166'!I22 -> NOS DIRIJIMOS DEL MUNICIPIO DE VILLAVICENCIO PARA TRANSPORTAR LA EXCAVADORA LINK BELT 2180 #5 DEL PUNTO DE TRABAJO EL DORADO, SECTOR LA ISLA Y NOS REGRESAMOS AL PATIO SERVIMACONS
... C28: =+'CAMABAJA OJT166'!C28 -> VILLAVICENCIO - PATIO GALICIA SERVIMACONS | D28: =+'CAMABAJA OJT166'!D28 -> GUAMAL - SECTOR PIO XII, RIO GUAMAL | E28: =+'CAMABAJA OJT166'!B28 -> 45840 | F28: =+'CAMABAJA OJT166'!B28 -> 45840 | G28: =+'CAMABAJA OJT166'!H28 -> 6 | H28: =+G28*'PLAN DE ACCIÓN'!$H$51 -> 0 | I28: =+'CAMABAJA OJT166'!I28 -> NOS DIRIJIMOS DEL MUNICIPIO DE VILLAVICENCIO PARA TRANSPORTAR LA EXCAVADORA LINK BELT 2180 #5 DEL PATIO GALICIA SERVIMACONS PARA EL PUNTO DE TRABAJO GUAMAL SECTOR PIO XII Y NOS REGRESAMOS AL PATIO SERVIMACONS
C29: =+'CAMABAJA OJT166'!C29 -> GUAMAL - SECTOR PIO XII, RIO GUAMAL | D29: =+'CAMABAJA OJT166'!D29 -> VILLAVICENCIO - PATIO GALICIA SERVIMACONS | E29: =+'CAMABAJA OJT166'!B29 -> 45847 | F29: =+'CAMABAJA OJT166'!B29 -> 45847 | G29: =+'CAMABAJA OJT166'!H29 -> 6 | H29: =+G29*'PLAN DE ACCIÓN'!$H$51 -> 0 | I29: =+'CAMABAJA OJT166'!I29 -> NOS DIRIJIMOS DEL MUNICIPIO DE VILLAVICENCIO PARA TRANSPORTAR LA EXCAVADORA LINK BELT 2180 #5 DEL PUNTO DE TRABAJO GUAMAL PIO XII PARA EL PATIO GALICIA SERVIMACONS | J29: EL TOTAL DE LAS HORAS DE LA CAMABAJA ES MAYOR AL AUTORIZADO
A30: TOTAL | G30: =SUM(G10:G29) -> 102 | H30: =SUM(H10:H29) -> 0
A31: 2 | B31: FUNCIONAMIENTO Y OPERACIÓN DE BULLDOZER SOBRE ORUGA CATERPILLAR D6K XL
B32: =+'2'!B10 -> BULLDOZER CATERPILLAR 2765 #2 | C32: =+'2'!C10 -> nombre municipio | D32: =+'2'!D10 -> nombre punto | E32: =+'2'!E10 -> 45769 | F32: =+'2'!F10 -> 45783 | G32: =+'2'!G10 -> 100 | H32: =+'2'!H10 -> 0 | I32: =+'2'!I10 -> SE REALIZA REHABILITACIÓN DE VIA EN EL PUNTO LA PAILA, RECORRIDO DE LA MAQUINA DEL PUNTO LA PAILA PARA EL DERRUMBE EN LA VEREDA EL CARMEN
B33: =+'2'!B11 -> BULLDOZER CATERPILLAR 2765 #2 | C33: =+'2'!C11 -> EL CALVARIO | D33: =+'2'!D11 -> SECTOR LAS BRUJAS | E33: =+'2'!E11 -> 45814 | F33: =+'2'!F11 -> 45825 | G33: =+'2'!G11 -> 188 | H33: =+'2'!H11 -> 0 | I33: =+'2'!I11 -> MAQUINA DISPONIBLE EN EL PUNTO DE TRABAJO, SE PRESENTAN FUERTES LLUVIAS EN EL SECTOR
B34: =+'2'!B12 -> #REF! | C34: =+'2'!C12 -> #REF! | D34: =+'2'!D12 -> #REF! | E34: =+'2'!E12 -> #REF! | F34: =+'2'!F12 -> #REF! | G34: =+'2'!G12 -> #REF! | H34: =+'2'!H12 -> #REF! | I34: =+'2'!I12 -> #REF!
A35: TOTAL | G35: =SUM(G32:G33) -> 288 | H35: =SUM(H32:H34) -> #REF!
A36: 3 | B36: FUNCIONAMIENTO Y OPERACIÓN DE EXCAVADORA SOBRE ORUGA LINK-BELT 210 X2, CAPACIDAD BALDE 1 M3 21 TONELADAS
B37: =+'BAJO POMPEYA - PALMARITO'!B9 -> EXCAVADORA LINK BELT 2181 #1 | C37: =+'BAJO POMPEYA - PALMARITO'!C9 -> VILLAVICENCIO | D37: =+'BAJO POMPEYA - PALMARITO'!D9 -> BAJO POMPEYA SECTOR PALMARITO, RIO GUAYURIBA | E37: =+'BAJO POMPEYA - PALMARITO'!E9 -> 45755 | F37: =+'BAJO POMPEYA - PALMARITO'!F9 -> 45777 | G37: =+'BAJO POMPEYA - PALMARITO'!G9 -> 127.2 | H37: =+'BAJO POMPEYA - PALMARITO'!H9 -> 0 | I37: =+'BAJO POMPEYA - PALMARITO'!I9 -> SE REALIZA EXCAVACIÓN EN EL CANAL PARA CONSTRUCIÓN DEL JARILLON Y PODER DESVIAR EL RIO
B38: =+'BAJO POMPEYA - PALMARITO'!B10 -> EXCAVADORA LINK BELT 2180 #5 | C38: =+'BAJO POMPEYA - PALMARITO'!C10 -> VILLAVICENCIO | D38: =+'BAJO POMPEYA - PALMARITO'!D10 -> BAJO POMPEYA SECTOR PALMARITO, RIO GUAYURIBA | E38: =+'BAJO POMPEYA - PALMARITO'!E10 -> 45755 | F38: =+'BAJO POMPEYA - PALMARITO'!F10 -> 45777 | G38: =+'BAJO POMPEYA - PALMARITO'!G10 -> 122.8 | H38: =+'BAJO POMPEYA - PALMARITO'!H10 -> 0 | I38: =+'BAJO POMPEYA - PALMARITO'!I10 -> SE REALIZA EXCAVACIÓN PARA DESVIAR UN BRAZO DEL RIO QUE ESTA RECOSTADO EN LA MARGEN IZQUIERDA
B39: =+'3'!B12 -> EXCAVADORA LINK BELT 2183 #3 | C39: =+'3'!C12 -> GUAMAL | D39: =+'3'!D12 -> SECTOR LA ISLA, RIO GUAMAL | E39: =+'3'!E12 -> 45757 | F39: =+'3'!F12 -> 45800 | G39: =+'3'!G12 -> 270 | H39: =+'3'!H12 -> 0 | I39: =+'3'!I12 -> SE REALIZA EXCAVACIÓN PARA CONSTRUCCIÓN DE UN JARILLON DE PROTECCIÓN
B40: =+'3'!B13 -> EXCAVADORA LINK BELT 2179 #4 | C40: =+'3'!C13 -> GUAMAL | D40: =+'3'!D13 -> SECTOR PIO XII, RIO GUAMAL | E40: =+'3'!E13 -> 45757 | F40: =+'3'!F13 -> 45784 | G40: =+'3'!G13 -> 130 | H40: =+'3'!H13 -> 0 | I40: =+'3'!I13 -> SE REALIZA CONSTRUCCIÓN DE JARILLON PARA QUITAR PRESION DE LA MARGEN IZQUIERDA AGUAS ABAJO Y SE CENTRA PARTE DEL RIO
B41: =+'3'!B14 -> EXCAVADORA LINK BELT 2181 #1 | C41: =+'3'!C14 -> EL CASTILLO | D41: =+'3'!D14 -> PUENTE LA AMISTAD, RIO ARIARI | E41: =+'3'!E14 -> 45779 | F41: =+'3'!F14 -> 45793 | G41: =+'3'!G14 -> 106.5 | H41: =+'3'!H14 -> 0 | I41: =+'3'!I14 -> SE TRANSPALEA MATERIAL PARA AMPLIACIÓN DE CANAL EN EL RIO ARIARI
B42: =+'3'!B15 -> EXCAVADORA LINK BELT 2180 #5 | C42: =+'3'!C15 -> EL CASTILLO | D42: =+'3'!D15 -> PUENTE LA AMISTAD, RIO ARIARI | E42: =+'3'!E15 -> 45784 | F42: =+'3'!F15 -> 45802 | G42: =+'3'!G15 -> 107.8 | H42: =+'3'!H15 -> 0 | I42: =+'3'!I15 -> SE REALIZA LA CONSTRUCCIÓN DEL CANAL PARA DESVIO DEL CAUCE DEL RIO
B43: =+'3'!B16 -> EXCAVADORA LINK BELT 2179 #4 | C43: =+'3'!C16 -> EL CASTILLO | D43: =+'3'!D16 -> PUENTE LA AMISTAD, RIO ARIARI | E43: =+'3'!E16 -> 45784 | F43: =+'3'!F16 -> 45804 | G43: =+'3'!G16 -> 8.7 | H43: =+'3'!H16 -> 0 | I43: =+'3'!I16 -> SE REALIZA LA CONSTRUCCIÓN DEL CANAL PARA DESVIO DEL CAUCE DEL RIO
B44: =+'3'!B17 -> EXCAVADORA LINK BELT 2181 #1 | C44: =+'3'!C17 -> EL CASTILLO | D44: =+'3'!D17 -> PUERTO ESPERANZA, RIO LA CAL | E44: =+'3'!E17 -> 45794 | F44: =+'3'!F17 -> 45807 | G44: =+'3'!G17 -> 117 | H44: =+'3'!H17 -> 0 | I44: =+'3'!I17 -> EXCAVACIÓN PARA CANAL Y SE CONFORMA JARILLON DE PROTECCIÓN
B45: =+'3'!B18 -> EXCAVADORA LINK BELT 2119 #4 | C45: =+'3'!C18 -> EL DORADO | D45: =+'3'!D18 -> RIO ARIARI | E45: =+'3'!E18 -> 45825 | F45: =+'3'!F18 -> 45849 | G45: =+'3'!G18 -> 100 | H45: =+'3'!H18 -> 0 | I45: =+'3'!I18 -> SE REALIZA EXCAVACIÓN PARA CONFORMACIÓN DE JARILLON DE PROTECCIÓN
B46: =+'3'!B19 -> EXCAVADORA LINK BELT 2183 #3 | C46: =+'3'!C19 -> SAN CARLOS DE GUAROA | D46: =+'3'!D19 -> SECTOR PUENTE TRES ARCOS | E46: =+'3'!E19 -> 45821 | F46: =+'3'!F19 -> 45838 | G46: =+'3'!G19 -> 100 | H46: =+'3'!H19 -> 0 | I46: =+'3'!I19 -> SE REALIZA ENROCADO EN LA MARGEN DERECHA AGUAS ABAJO PARA MITIGAR DESBORDAMIENTO EN EL TERRAPLEN DE LA CARRETERA Y REHABILITAR EL PASO EN EL PUENTE
B47: =+#REF! -> #REF! | C47: =+#REF! -> #REF! | D47: =+#REF! -> #REF! | E47: =+#REF! -> #REF! | F47: =+#REF! -> #REF! | G47: =+#REF! -> #REF! | H47: =+#REF! -> #REF! | I47: =+#REF! -> #REF!
...

Sheet 1
A1: RESUMEN GENERAL DE ACTIVIDADES EJECUTADAS
A2: CONTRATO Nº:
A3: OBJETO:
A4: PERIODO DEL INFORME: | F4: AL
A5: FECHA PRESENTE ACTA:
A8: ITEM | B8: DESCRIPCIÓN / MAQUINA | C8: MUNICIPIO | D8: PUNTO | E8: FECHA INICIO | F8: FECHA FINAL | G8: HORAS EJECUTADAS | H8: VALOR EJECUTADO | I8: ACTIVIDAD REALIZADA
A9: 1 | B9: FUNCIONAMIENTO Y OPERACIÓN DE TRACTO-CAMIÓN INTERNACIONAL 7600 CAPACIDAD CARGA 35 TONELADAS CON ACCESORIO CAMABAJA
B10: =+'CAMABAJA INTERNACIONAL OJT166'!B9 -> CAMABAJA INTERNATIONAL OJT166 | C10: =+'CAMABAJA OJT166'!C10 -> VILLAVICENCIO - PATIO GALICIA SERVIMACONS | D10: =+'CAMABAJA OJT166'!D10 -> BAJO POMPEYA SECTOR PALMARITO, RIO GUAYURIBA | E10: =+'CAMABAJA OJT166'!B10 -> 45755 | F10: =+E10 -> 45755 | G10: =+'CAMABAJA OJT166'!H10 -> 4 | H10: =+'1'!G10*'PLAN DE ACCIÓN'!H51 -> 0 | I10: =+'CAMABAJA OJT166'!I10 -> NOS DIRIJIMOS DEL MUNICIPIO DE VILLAVICENCIO PARA TRANSPORTAR LA EXCAVADORA LINK BELT 2181 #1 DEL PATIO GALICIA SERVIMACONS PARA EL PUNTO DE TRABAJO BAJO POMPEYA SECTOR PALMARITO, RIO GUAYURIBA Y NOS REGRESAMOS AL PATIO SERVIMACONS
C11: =+'CAMABAJA OJT166'!C11 -> VILLAVICENCIO - PATIO GALICIA SERVIMACONS | D11: =+'CAMABAJA OJT166'!D11 -> BAJO POMPEYA SECTOR PALMARITO, RIO GUAYURIBA | E11: =+'CAMABAJA OJT166'!B11 -> 45755 | F11: =+E11 -> 45755 | G11: =+'CAMABAJA OJT166'!H11 -> 4 | H11: =+G11*'PLAN DE ACCIÓN'!H51 -> 0 | I11: =+'CAMABAJA OJT166'!I11 -> NOS DIRIJIMOS DEL MUNICIPIO DE VILLAVICENCIO PARA TRANSPORTAR LA EXCAVADORA LINK BELT 2180 #5 DEL PATIO GALICIA SERVIMACONS PARA EL PUNTO DE TRABAJO BAJO POMPEYA SECTOR PALMARITO, RIO GUAYURIBA Y NOS REGRESAMOS AL PATIO SERVIMACONS
C12: =+'CAMABAJA OJT166'!C12 -> VILLAVICENCIO - PATIO GALICIA SERVIMACONS | D12: =+'CAMABAJA OJT166'!D12 -> SECTOR LA ISLA, RIO GUAMAL | E12: =+'CAMABAJA OJT166'!B12 -> 45756 | F12: =+E12 -> 45756 | G12: =+'CAMABAJA OJT166'!H12 -> 8 | H12: =+G12*'PLAN DE ACCIÓN'!H51 -> 0 | I12: =+'CAMABAJA OJT166'!I12 -> NOS DIRIJIMOS DEL MUNICIPIO DE VILLAVICENCIO PARA TRANSPORTAR LA EXCAVADORA LINK BELT 2183 #3 DEL PATIO GALICIA SERVIMACONS PARA EL PUNTO DE TRABAJO SECTOR LA ISLA RIO GUAMAL Y NOS REGRESAMOS AL PATIO SERVIMACONS
C13: =+'CAMABAJA INTERNACIONAL OJT166'!C12 -> VILLAVICENCIO - PATIO GALICIA SERVIMACONS | D13: =+'CAMABAJA INTERNACIONAL OJT166'!D12 -> SECTOR PIO XII, RIO GUAMAL | E13: =+'CAMABAJA INTERNACIONAL OJT166'!E12 -> 45757 | F13: =+'CAMABAJA INTERNACIONAL OJT166'!F12 -> 45757 | G13: =+'CAMABAJA INTERNACIONAL OJT166'!G12 -> 4 | H13: =+'CAMABAJA INTERNACIONAL OJT166'!H12 -> 0 | I13: =+'CAMABAJA INTERNACIONAL OJT166'!I12 -> NOS DIRIJIMOS DEL MUNICIPIO DE VILLAVICENCIO PARA TRANSPORTAR LA EXCAVADORA LINK BELT 2179 #4 DEL PATIO GALICIA SERVIMACONS PARA EL PUNTO DE TRABAJO SECTOR PIO XII RIO GUAMAL Y NOS REGRESAMOS AL PATIO SERVIMACONS
C14: =+'CAMABAJA INTERNACIONAL OJT166'!C13 -> EL CALVARIO | D14: =+'CAMABAJA INTERNACIONAL OJT166'!D13 -> VIA MONFORTH | E14: =+'CAMABAJA INTERNACIONAL OJT166'!E13 -> 45770 | F14: =+'CAMABAJA INTERNACIONAL OJT166'!F13 -> 45770 | G14: =+'CAMABAJA INTERNACIONAL OJT166'!G13 -> 3 | H14: =+'CAMABAJA INTERNACIONAL OJT166'!H13 -> 0 | I14: =+'CAMABAJA INTERNACIONAL OJT166'!I13 -> NOS DIRIJIMOS DEL MUNICIPIO DE VILLAVICENCIO PARA TRANSPORTAR LA RETROEXCAVADORA CATERPILLAR 8585 416E DEL PATIO GALICIA SERVIMACONS PARA LA VIA MONFORTH Y NOS REGRESAMOS AL PATIO SERVIMACONS
C15: =+'CAMABAJA INTERNACIONAL OJT166'!C14 -> BAJO POMPEYA SECTOR PALMARITO, RIO GUAYURIBA | D15: =+'CAMABAJA INTERNACIONAL OJT166'!D14 -> VILLAVICENCIO - PATIO GALICIA SERVIMACONS | E15: =+'CAMABAJA INTERNACIONAL OJT166'!E14 -> 45777 | F15: =+'CAMABAJA INTERNACIONAL OJT166'!F14 -> 45777 | G15: =+'CAMABAJA INTERNACIONAL OJT166'!G14 -> 4 | H15: =+'CAMABAJA INTERNACIONAL OJT166'!H14 -> 0 | I15: =+'CAMABAJA INTERNACIONAL OJT166'!I14 -> NOS DIRIJIMOS DEL MUNICIPIO DE VILLAVICENCIO PARA TRANSPORTAR LA EXCAVADORA LINK BELT 2181 #1 DEL PUNTO DE TRABAJO BAJO POMPEYA PARA EL PATIO GALICIA SERVIMACONS
C16: =+'CAMABAJA INTERNACIONAL OJT166'!C15 -> BAJO POMPEYA SECTOR PALMARITO, RIO GUAYURIBA | D16: =+'CAMABAJA INTERNACIONAL OJT166'!D15 -> VILLAVICENCIO - PATIO GALICIA SERVIMACONS | E16: =+'CAMABAJA INTERNACIONAL OJT166'!E15 -> 45777 | F16: =+'CAMABAJA INTERNACIONAL OJT166'!F15 -> 45777 | G16: =+'CAMABAJA INTERNACIONAL OJT166'!G15 -> 4 | H16: =+'CAMABAJA INTERNACIONAL OJT166'!H15 -> 0 | I16: =+'CAMABAJA INTERNACIONAL OJT166'!I15 -> NOS DIRIJIMOS DEL MUNICIPIO DE VILLAVICENCIO PARA TRANSPORTAR LA EXCAVADORA LINK BELT 2180 #5 DEL PUNTO DE TRABAJO BAJO POMPEYA PARA EL PATIO GALICIA SERVIMACONS
C17: =+'CAMABAJA INTERNACIONAL OJT166'!C16 -> VILLAVICENCIO - PATIO GALICIA SERVIMACONS | D17: =+'CAMABAJA INTERNACIONAL OJT166'!D16 -> EL DORADO, SECTOR LA ISLA RIO ARIARI | E17: =+'CAMABAJA INTERNACIONAL OJT166'!E16 -> 45778 | F17: =+'CAMABAJA INTERNACIONAL OJT166'!F16 -> 45778 | G17: =+'CAMABAJA INTERNACIONAL OJT166'!G16 -> 5 | H17: =+'CAMABAJA INTERNACIONAL OJT166'!H16 -> 0 | I17: =+'CAMABAJA INTERNACIONAL OJT166'!I16 -> NOS DIRIJIMOS DEL MUNICIPIO DE VILLAVICENCIO PARA TRANSPORTAR LA EXCAVADORA LINK BELT 2181 #1 DEL PATIO SERVIMACONS PARA EL PUNTO DE TRABAJO EL DORADO PUENTE LA AMISTAD Y NOS REGRESAMOS AL PATIO SERVIMACONS
C18: =+'CAMABAJA INTERNACIONAL OJT166'!C17 -> VILLAVICENCIO - PATIO GALICIA SERVIMACONS | D18: =+'CAMABAJA INTERNACIONAL OJT166'!D17 -> EL DORADO, SECTOR LA ISLA RIO ARIARI | E18: =+'CAMABAJA INTERNACIONAL OJT166'!E17 -> 45784 | F18: =+'CAMABAJA INTERNACIONAL OJT166'!F17 -> 45784 | G18: =+'CAMABAJA INTERNACIONAL OJT166'!G17 -> 4 | H18: =+'CAMABAJA INTERNACIONAL OJT166'!H17 -> 0 | I18: =+'CAMABAJA INTERNACIONAL OJT166'!I17 -> NOS DIRIJIMOS DEL MUNICIPIO DE VILLAVICENCIO PARA TRANSPORTAR LA EXCAVADORA LINK BELT 2180 #5 DEL PATIO GALICIA SERVIMACONS PARA EL PUNTO DE TRABAJO EL DORADO, SECTOR LA ISLA RIO ARIARI Y NOS DIRIJIMOS AL MUNICIPIO DE GUAMAL
C19: =+'CAMABAJA INTERNACIONAL OJT166'!C18 -> VILLAVICENCIO - PATIO GALICIA SERVIMACONS | D19: =+'CAMABAJA INTERNACIONAL OJT166'!D18 -> EL DORADO, SECTOR LA ISLA RIO ARIARI | E19: =+'CAMABAJA INTERNACIONAL OJT166'!E18 -> 45784 | F19: =+'CAMABAJA INTERNACIONAL OJT166'!F18 -> 45784 | G19: =+'CAMABAJA INTERNACIONAL OJT166'!G18 -> 4 | H19: =+'CAMABAJA INTERNACIONAL OJT166'!H18 -> 0 | I19: =+'CAMABAJA INTERNACIONAL OJT166'!I18 -> NOS DIRIJIMOS DEL MUNICIPIO DE VILLAVICENCIO PARA TRANSPORTAR LA EXCAVADORA LINK BELT 2179 #4 DEL PUNTO DE TRABAJO PIO XII PARA EL PUNTO DE TRABAJO EL DORARO SECTOR LA ISLA RIO ARIARI Y NOS REGRESAMOS AL PATIO SERVIMACONS
C20: =+'CAMABAJA INTERNACIONAL OJT166'!C19 -> EL DORADO, SECTOR LA ISLA RIO ARIARI | D20: =+'CAMABAJA INTERNACIONAL OJT166'!D19 -> SECTOR PUERTO ESPERANZA | E20: =+'CAMABAJA INTERNACIONAL OJT166'!E19 -> 45794 | F20: =+'CAMABAJA INTERNACIONAL OJT166'!F19 -> 45794 | G20: =+'CAMABAJA INTERNACIONAL OJT166'!G19 -> 4 | H20: =+'CAMABAJA INTERNACIONAL OJT166'!H19 -> 0 | I20: =+'CAMABAJA INTERNACIONAL OJT166'!I19 -> NOS DIRIJIMOS DEL MUNICIPIO DE VILLAVICENCIO PARA TRANSPORTAR LA EXCAVADORA LINK BELT 2179 #4 DEL PUNTO DE TRABAJO SECTOR LA ISLA RIO ARIARI PARA EL PUNTO PUERTO ESPERANZA Y NOS REGRESAMOS AL PATIO SERVIMACONS
C21: =+'CAMABAJA INTERNACIONAL OJT166'!C20 -> GUAMAL, SECTOR LA ISLA RIO GUAMAL | D21: =+'CAMABAJA INTERNACIONAL OJT166'!D20 -> VILLAVICENCIO - PATIO GALICIA SERVIMACONS | E21: =+'CAMABAJA INTERNACIONAL OJT166'!E20 -> 45800 | F21: =+'CAMABAJA INTERNACIONAL OJT166'!F20 -> 45800 | G21: =+'CAMABAJA INTERNACIONAL OJT166'!G20 -> 4 | H21: =+'CAMABAJA INTERNACIONAL OJT166'!H20 -> 0 | I21: =+'CAMABAJA INTERNACIONAL OJT166'!I20 -> NOS DIRIJIMOS DEL MUNICIPIO DE VILLAVICENCIO PARA TRANSPORTAR LA EXCAVADORA LINK BELT 2183 #3 DEL PUNTO DE TRABAJO GUAMAL, SECTOR LA ISLA RIO ARIARI Y NOS REGRESAMOS AL PATIO SERVIMACONS
C22: =+'CAMABAJA INTERNACIONAL OJT166'!C21 -> EL DORADO, SECTOR LA ISLA RIO ARIARI | D22: =+'CAMABAJA INTERNACIONAL OJT166'!D21 -> VILLAVICENCIO - PATIO GALICIA SERVIMACONS | E22: =+'CAMABAJA INTERNACIONAL OJT166'!E21 -> 45801 | F22: =+'CAMABAJA INTERNACIONAL OJT166'!F21 -> 45801 | G22: =+'CAMABAJA INTERNACIONAL OJT166'!G21 -> 5 | H22: =+'CAMABAJA INTERNACIONAL OJT166'!H21 -> 0 | I22: =+'CAMABAJA INTERNACIONAL OJT166'!I21 -> NOS DIRIJIMOS DEL MUNICIPIO DE VILLAVICENCIO PARA TRANSPORTAR LA EXCAVADORA LINK BELT 2180 #5 DEL PUNTO DE TRABAJO EL DORADO, SECTOR LA ISLA Y NOS REGRESAMOS AL PATIO SERVIMACONS
C23: =+'CAMABAJA INTERNACIONAL OJT166'!C22 -> EL DORADO, SECTOR LA ISLA RIO ARIARI | D23: =+'CAMABAJA INTERNACIONAL OJT166'!D22 -> VILLAVICENCIO - PATIO GALICIA SERVIMACONS | E23: =+'CAMABAJA INTERNACIONAL OJT166'!E22 -> 45804 | F23: =+'CAMABAJA INTERNACIONAL OJT166'!F22 -> 45804 | G23: =+'CAMABAJA INTERNACIONAL OJT166'!G22 -> 4 | H23: =+'CAMABAJA INTERNACIONAL OJT166'!H22 -> 0 | I23: =+'CAMABAJA INTERNACIONAL OJT166'!I22 -> NOS DIRIJIMOS DEL MUNICIPIO DE VILLAVICENCIO PARA TRANSPORTAR LA EXCAVADORA LINK BELT 2179 #4 DEL PUNTO DE TRABAJO EL DORADO SECTOR LA ISLA Y NOS REGRESAMOS AL PATIO SERVIMACONS
C24: =+'CAMABAJA INTERNACIONAL OJT166'!C23 -> VILLAVICENCIO - PATIO GALICIA SERVIMACONS | D24: =+'CAMABAJA INTERNACIONAL OJT166'!D23 -> SAN CARLOS DE GUAROA, PUENTE TRES ARCOS | E24: =+'CAMABAJA INTERNACIONAL OJT166'!E23 -> 45825 | F24: =+'CAMABAJA INTERNACIONAL OJT166'!F23 -> 45825 | G24: =+'CAMABAJA INTERNACIONAL OJT166'!G23 -> 7 | H24: =+'CAMABAJA INTERNACIONAL OJT166'!H23 -> 0 | I24: =+'CAMABAJA INTERNACIONAL OJT166'!I23 -> NOS DIRIJIMOS DEL MUNICIPIO DE VILLAVICENCIO PARA TRANSPORTAR LA EXCAVADORA LINK BELT 2183 #3 DEL PATIO GALICIA SERVIMACONS PARA EL PUNTO DE TRABAJO SAN CARLOS DE GUAROA PUENTE TRES ARCOS
... C27: =+'CAMABAJA INTERNACIONAL OJT166'!C26 -> SAN CARLOS DE GUAROA, PUENTE TRES ARCOS | D27: =+'CAMABAJA INTERNACIONAL OJT166'!D26 -> VILLAVICENCIO - PATIO GALICIA SERVIMACONS | E27: =+'CAMABAJA INTERNACIONAL OJT166'!E26 -> 45839 | F27: =+'CAMABAJA INTERNACIONAL OJT166'!F26 -> 45839 | G27: =+'CAMABAJA INTERNACIONAL OJT166'!G26 -> 6 | H27: =+'CAMABAJA INTERNACIONAL OJT166'!H26 -> 0 | I27: =+'CAMABAJA INTERNACIONAL OJT166'!I26 -> NOS DIRIJIMMOS DEL MUNICIPIO DE VILLAVICENCIO PARA TRANSPORTAR LA EXCAVADORA LINK BELT 2183 #3 DEL PUNTO DE TRABAJO SAN CARLOS DE GUAROA PARA EL PATIO GALICIA SERVIMACONS
B29: SUBTOTAL | H29: =SUM(H10:H28) -> 0
B30: IVA 19% | H30: =+H29*0.19 -> 0
B31: TOTAL | H31: =+H30+H29 -> 0
B36: LUIS MIGUEL ANGEL RAMIREZ ROMERO
B37: Rep. Legal SERVICIOS MAQUINARIA Y CONSTRUCCIONES SAS "SERVIMACONS S.A.S."
B38: CONTRATISTA

Sheet 2
A1: RESUMEN GENERAL DE ACTIVIDADES EJECUTADAS
A2: CONTRATO Nº:
A3: OBJETO:
A4: PERIODO DEL INFORME: | F4: AL
A5: FECHA PRESENTE ACTA:
A8: ITEM | B8: DESCRIPCIÓN / MAQUINA | C8: MUNICIPIO | D8: PUNTO | E8: FECHA INICIO | F8: FECHA FINAL | G8: HORAS EJECUTADAS | H8: VALOR EJECUTADO | I8: ACTIVIDAD REALIZADA
A9: 2 | B9: FUNCIONAMIENTO Y OPERACIÓN DE BULLDOZER SOBRE ORUGA CATERPILLAR D6K XL
B10: =+'EL CALVARIO - CARMEN, BENITO'!B9 -> BULLDOZER CATERPILLAR 2765 #2 | C10: =+'EL CALVARIO - CARMEN, BENITO'!C9 -> nombre municipio | D10: =+'EL CALVARIO - CARMEN, BENITO'!D9 -> nombre punto | E10: =+'EL CALVARIO - CARMEN, BENITO'!E9 -> 45769 | F10: =+'EL CALVARIO - CARMEN, BENITO'!F9 -> 45783 | G10: =+'EL CALVARIO - CARMEN, BENITO'!G9 -> 100 | H10: =+'EL CALVARIO - CARMEN, BENITO'!H9 -> 0 | I10: =+'EL CALVARIO - CARMEN, BENITO'!I9 -> SE REALIZA REHABILITACIÓN DE VIA EN EL PUNTO LA PAILA, RECORRIDO DE LA MAQUINA DEL PUNTO LA PAILA PARA EL DERRUMBE EN LA VEREDA EL CARMEN
B11: =+'BULLDOZER CATERPILLAR 2765 #2.'!B9 -> BULLDOZER CATERPILLAR 2765 #2 | C11: =+'BULLDOZER CATERPILLAR 2765 #2.'!C9 -> EL CALVARIO | D11: =+'BULLDOZER CATERPILLAR 2765 #2.'!D9 -> SECTOR LAS BRUJAS | E11: =+'BULLDOZER CATERPILLAR 2765 #2.'!E9 -> 45814 | F11: =+'BULLDOZER CATERPILLAR 2765 #2.'!F9 -> 45825 | G11: =+'BULLDOZER CATERPILLAR 2765 #2.'!G9 -> 188 | H11: =+'BULLDOZER CATERPILLAR 2765 #2.'!H9 -> 0 | I11: =+'BULLDOZER CATERPILLAR 2765 #2.'!I9 -> MAQUINA DISPONIBLE EN EL PUNTO DE TRABAJO, SE PRESENTAN FUERTES LLUVIAS EN EL SECTOR
B12: =+#REF! -> #REF! | C12: =+#REF! -> #REF! | D12: =+#REF! -> #REF! | E12: =+#REF! -> #REF! | F12: =+#REF! -> #REF! | G12: =+#REF! -> #REF! | H12: =+#REF! -> #REF! | I12: =+#REF! -> #REF!
B13: SUBTOTAL | H13: =SUM(H10:H12) -> #REF!
B14: IVA 19% | H14: =+H13*0.19 -> #REF!
B15: TOTAL | H15: =+H14+H13 -> #REF!
B20: LUIS MIGUEL ANGEL RAMIREZ ROMERO
B21: Rep. Legal SERVICIOS MAQUINARIA Y CONSTRUCCIONES SAS "SERVIMACONS S.A.S."
B22: CONTRATISTA

Sheet 3
A1: RESUMEN GENERAL DE ACTIVIDADES EJECUTADAS
A2: CONTRATO Nº:
A3: OBJETO:
A4: PERIODO DEL INFORME: | F4: AL
A5: FECHA PRESENTE ACTA:
A8: ITEM | B8: DESCRIPCIÓN / MAQUINA | C8: MUNICIPIO | D8: PUNTO | E8: FECHA INICIO | F8: FECHA FINAL | G8: HORAS EJECUTADAS | H8: VALOR EJECUTADO | I8: ACTIVIDAD REALIZADA
A9: 3 | B9: FUNCIONAMIENTO Y OPERACIÓN DE EXCAVADORA SOBRE ORUGA LINK-BELT 210 X2, CAPACIDAD BALDE 1 M3 21 TONELADAS
B10: =+'BAJO POMPEYA - PALMARITO'!B9 -> EXCAVADORA LINK BELT 2181 #1 | C10: =+'BAJO POMPEYA - PALMARITO'!C9 -> VILLAVICENCIO | D10: =+'BAJO POMPEYA - PALMARITO'!D9 -> BAJO POMPEYA SECTOR PALMARITO, RIO GUAYURIBA | E10: =+'BAJO POMPEYA - PALMARITO'!E9 -> 45755 | F10: =+'BAJO POMPEYA - PALMARITO'!F9 -> 45777 | G10: =+'BAJO POMPEYA - PALMARITO'!G9 -> 127.2 | H10: =+'BAJO POMPEYA - PALMARITO'!H9 -> 0 | I10: =+'BAJO POMPEYA - PALMARITO'!I9 -> SE REALIZA EXCAVACIÓN EN EL CANAL PARA CONSTRUCIÓN DEL JARILLON Y PODER DESVIAR EL RIO
B11: =+'BAJO POMPEYA - PALMARITO'!B10 -> EXCAVADORA LINK BELT 2180 #5 | C11: =+'BAJO POMPEYA - PALMARITO'!C10 -> VILLAVICENCIO | D11: =+'BAJO POMPEYA - PALMARITO'!D10 -> BAJO POMPEYA SECTOR PALMARITO, RIO GUAYURIBA | E11: =+'BAJO POMPEYA - PALMARITO'!E10 -> 45755 | F11: =+'BAJO POMPEYA - PALMARITO'!F10 -> 45777 | G11: =+'BAJO POMPEYA - PALMARITO'!G10 -> 122.8 | H11: =+'BAJO POMPEYA - PALMARITO'!H10 -> 0 | I11: =+'BAJO POMPEYA - PALMARITO'!I10 -> SE REALIZA EXCAVACIÓN PARA DESVIAR UN BRAZO DEL RIO QUE ESTA RECOSTADO EN LA MARGEN IZQUIERDA
B12: =+'EXCA LINK BELT 2183 #3'!B9 -> EXCAVADORA LINK BELT 2183 #3 | C12: =+'EXCA LINK BELT 2183 #3'!C9 -> GUAMAL | D12: =+'EXCA LINK BELT 2183 #3'!D9 -> SECTOR LA ISLA, RIO GUAMAL | E12: =+'EXCA LINK BELT 2183 #3'!E9 -> 45757 | F12: =+'EXCA LINK BELT 2183 #3'!F9 -> 45800 | G12: =+'EXCA LINK BELT 2183 #3'!G9 -> 270 | H12: =+'EXCA LINK BELT 2183 #3'!H9 -> 0 | I12: =+'EXCA LINK BELT 2183 #3'!I9 -> SE REALIZA EXCAVACIÓN PARA CONSTRUCCIÓN DE UN JARILLON DE PROTECCIÓN
B13: =+'EXCA LINK BELT 2179 #4'!B9 -> EXCAVADORA LINK BELT 2179 #4 | C13: =+'EXCA LINK BELT 2179 #4'!C9 -> GUAMAL | D13: =+'EXCA LINK BELT 2179 #4'!D9 -> SECTOR PIO XII, RIO GUAMAL | E13: =+'EXCA LINK BELT 2179 #4'!E9 -> 45757 | F13: =+'EXCA LINK BELT 2179 #4'!F9 -> 45784 | G13: =+'EXCA LINK BELT 2179 #4'!G9 -> 130 | H13: =+'EXCA LINK BELT 2179 #4'!H9 -> 0 | I13: =+'EXCA LINK BELT 2179 #4'!I9 -> SE REALIZA CONSTRUCCIÓN DE JARILLON PARA QUITAR PRESION DE LA MARGEN IZQUIERDA AGUAS ABAJO Y SE CENTRA PARTE DEL RIO
B14: =+'EL CASTILLO-PUENTE LA AMISTAD'!B9 -> EXCAVADORA LINK BELT 2181 #1 | C14: =+'EL CASTILLO-PUENTE LA AMISTAD'!C9 -> EL CASTILLO | D14: =+'EL CASTILLO-PUENTE LA AMISTAD'!D9 -> PUENTE LA AMISTAD, RIO ARIARI | E14: =+'EL CASTILLO-PUENTE LA AMISTAD'!E9 -> 45779 | F14: =+'EL CASTILLO-PUENTE LA AMISTAD'!F9 -> 45793 | G14: =+'EL CASTILLO-PUENTE LA AMISTAD'!G9 -> 106.5 | H14: =+'EL CASTILLO-PUENTE LA AMISTAD'!H9 -> 0 | I14: =+'EL CASTILLO-PUENTE LA AMISTAD'!I9 -> SE TRANSPALEA MATERIAL PARA AMPLIACIÓN DE CANAL EN EL RIO ARIARI
B15: =+'EL CASTILLO-PUENTE LA AMISTAD'!B10 -> EXCAVADORA LINK BELT 2180 #5 | C15: =+'EL CASTILLO-PUENTE LA AMISTAD'!C10 -> EL CASTILLO | D15: =+'EL CASTILLO-PUENTE LA AMISTAD'!D10 -> PUENTE LA AMISTAD, RIO ARIARI | E15: =+'EL CASTILLO-PUENTE LA AMISTAD'!E10 -> 45784 | F15: =+'EL CASTILLO-PUENTE LA AMISTAD'!F10 -> 45802 | G15: =+'EL CASTILLO-PUENTE LA AMISTAD'!G10 -> 107.8 | H15: =+'EL CASTILLO-PUENTE LA AMISTAD'!H10 -> 0 | I15: =+'EL CASTILLO-PUENTE LA AMISTAD'!I10 -> SE REALIZA LA CONSTRUCCIÓN DEL CANAL PARA DESVIO DEL CAUCE DEL RIO
B16: =+'EL CASTILLO-PUENTE LA AMISTAD'!B11 -> EXCAVADORA LINK BELT 2179 #4 | C16: =+'EL CASTILLO-PUENTE LA AMISTAD'!C11 -> EL CASTILLO | D16: =+'EL CASTILLO-PUENTE LA AMISTAD'!D11 -> PUENTE LA AMISTAD, RIO ARIARI | E16: =+'EL CASTILLO-PUENTE LA AMISTAD'!E11 -> 45784 | F16: =+'EL CASTILLO-PUENTE LA AMISTAD'!F11 -> 45804 | G16: =+'EL CASTILLO-PUENTE LA AMISTAD'!G11 -> 8.7 | H16: =+'EL CASTILLO-PUENTE LA AMISTAD'!H11 -> 0 | I16: =+'EL CASTILLO-PUENTE LA AMISTAD'!I11 -> SE REALIZA LA CONSTRUCCIÓN DEL CANAL PARA DESVIO DEL CAUCE DEL RIO
B17: =+'EXCA LINK BELT 2181. #1'!B9 -> EXCAVADORA LINK BELT 2181 #1 | C17: =+'EXCA LINK BELT 2181. #1'!C9 -> EL CASTILLO | D17: =+'EXCA LINK BELT 2181. #1'!D9 -> PUERTO ESPERANZA, RIO LA CAL | E17: =+'EXCA LINK BELT 2181. #1'!E9 -> 45794 | F17: =+'EXCA LINK BELT 2181. #1'!F9 -> 45807 | G17: =+'EXCA LINK BELT 2181. #1'!G9 -> 117 | H17: =+'EXCA LINK BELT 2181. #1'!H9 -> 0 | I17: =+'EXCA LINK BELT 2181. #1'!I9 -> EXCAVACIÓN PARA CANAL Y SE CONFORMA JARILLON DE PROTECCIÓN
B18: =+'EXCA LINK BEL T 2179 #.4'!B9 -> EXCAVADORA LINK BELT 2119 #4 | C18: =+'EXCA LINK BEL T 2179 #.4'!C9 -> EL DORADO | D18: =+'EXCA LINK BEL T 2179 #.4'!D9 -> RIO ARIARI | E18: =+'EXCA LINK BEL T 2179 #.4'!E9 -> 45825 | F18: =+'EXCA LINK BEL T 2179 #.4'!F9 -> 45849 | G18: =+'EXCA LINK BEL T 2179 #.4'!G9 -> 100 | H18: =+'EXCA LINK BEL T 2179 #.4'!H9 -> 0 | I18: =+'EXCA LINK BEL T 2179 #.4'!I9 -> SE REALIZA EXCAVACIÓN PARA CONFORMACIÓN DE JARILLON DE PROTECCIÓN
B19: =+'EXCA LINK BEL T 2183 #3'!B9 -> EXCAVADORA LINK BELT 2183 #3 | C19: =+'EXCA LINK BEL T 2183 #3'!C9 -> SAN CARLOS DE GUAROA | D19: =+'EXCA LINK BEL T 2183 #3'!D9 -> SECTOR PUENTE TRES ARCOS | E19: =+'EXCA LINK BEL T 2183 #3'!E9 -> 45821 | F19: =+'EXCA LINK BEL T 2183 #3'!F9 -> 45838 | G19: =+'EXCA LINK BEL T 2183 #3'!G9 -> 100 | H19: =+'EXCA LINK BEL T 2183 #3'!H9 -> 0 | I19: =+'EXCA LINK BEL T 2183 #3'!I9 -> SE REALIZA ENROCADO EN LA MARGEN DERECHA AGUAS ABAJO PARA MITIGAR DESBORDAMIENTO EN EL TERRAPLEN DE LA CARRETERA Y REHABILITAR EL PASO EN EL PUENTE
